{
  "version": 8,
  "blockIdVersion": 11,
  "anchorX": 0,
  "anchorY": 0,
  "anchorZ": 0,
  "blocks": [
    {
      "x": -55,
      "y": 38,
      "z": -38,
      "name": "Rock_Volcanic"
    },
    {
      "x": -55,
      "y": 39,
      "z": -38,
      "name": "Rock_Volcanic"
    },
    {
      "x": -55,
      "y": 40,
      "z": -38,
      "name": "Rock_Volcanic"
    },
    {
      "x": -55,
      "y": 41,
      "z": -38,
      "name": "Rock_Volcanic"
    },
    {
      "x": -55,
      "y": 42,
      "z": -38,
      "name": "Rock_Volcanic_Brick"
    },
    {
      "x": -55,
      "y": 43,
      "z": -38,
      "name": "Rock_Volcanic_Brick"
    },
    {
      "x": -55,
      "y": 44,
      "z": -38,
      "name": "Rock_Volcanic_Brick"
    },
    {
      "x": -55,
      "y": 45,
      "z": -38,
      "name": "Rock_Volcanic_Brick"
    },
    {
      "x": -55,
      "y": 46,
      "z": -38,
      "name": "Rock_Volcanic_Brick"
    },
    {
      "x": -55,
      "y": 47,
      "z": -38,
      "name": "Rock_Volcanic_Brick"
    },
    {
      "x": -55,
      "y": 48,
      "z": -38,
      "name": "Rock_Volcanic_Brick"
    },
    {
      "x": -55,
      "y": 49,
      "z": -38,
      "name": "Rock_Volcanic_Brick"
    },
    {
      "x": -55,
      "y": 50,
      "z": -38,
      "name": "Rock_Volcanic_Brick"
    },
    {
      "x": -55,
      "y": 51,
      "z": -38,
      "name": "Rock_Volcanic_Brick"
    },
    {
      "x": -55,
      "y": 38,
      "z": -37,
      "name": "Rock_Volcanic"
    },
    {
      "x": -55,
      "y": 39,
      "z": -37,
      "name": "Rock_Volcanic"
    },
    {
      "x": -55,
      "y": 40,
      "z": -37,
      "name": "Rock_Volcanic"
    },
    {
      "x": -55,
      "y": 41,
      "z": -37,
      "name": "Rock_Volcanic_Cobble"
    },
    {
      "x": -55,
      "y": 42,
      "z": -37,
      "name": "Rock_Volcanic_Cobble"
    },
    {
      "x": -55,
      "y": 43,
      "z": -37,
      "name": "Rock_Volcanic_Brick"
    },
    {
      "x": -55,
      "y": 44,
      "z": -37,
      "name": "Rock_Volcanic_Brick"
    },
    {
      "x": -55,
      "y": 45,
      "z": -37,
      "name": "Rock_Volcanic_Brick"
    },
    {
      "x": -55,
      "y": 46,
      "z": -37,
      "name": "Rock_Volcanic_Brick"
    },
    {
      "x": -55,
      "y": 47,
      "z": -37,
      "name": "Rock_Volcanic_Brick"
    },
    {
      "x": -55,
      "y": 48,
      "z": -37,
      "name": "Rock_Volcanic_Brick"
    },
    {
      "x": -55,
      "y": 49,
      "z": -37,
      "name": "Rock_Volcanic_Brick"
    },
    {
      "x": -55,
      "y": 50,
      "z": -37,
      "name": "Rock_Volcanic_Brick"
    },
    {
      "x": -55,
      "y": 38,
      "z": -15,
      "name": "Rock_Volcanic_Cobble"
    },
    {
      "x": -55,
      "y": 39,
      "z": -15,
      "name": "Rock_Volcanic_Cobble"
    },
    {
      "x": -55,
      "y": 40,
      "z": -15,
      "name": "Rock_Volcanic_Cobble"
    },
    {
      "x": -55,
      "y": 41,
      "z": -15,
      "name": "Rock_Volcanic_Cobble"
    },
    {
      "x": -55,
      "y": 42,
      "z": -15,
      "name": "Rock_Volcanic_Cobble"
    },
    {
      "x": -55,
      "y": 43,
      "z": -15,
      "name": "Rock_Volcanic_Brick"
    },
    {
      "x": -55,
      "y": 44,
      "z": -15,
      "name": "Rock_Volcanic_Brick"
    },
    {
      "x": -55,
      "y": 45,
      "z": -15,
      "name": "Rock_Volcanic_Brick"
    },
    {
      "x": -55,
      "y": 46,
      "z": -15,
      "name": "Rock_Volcanic_Brick"
    },
    {
      "x": -55,
      "y": 47,
      "z": -15,
      "name": "Rock_Volcanic_Brick"
    },
    {
      "x": -55,
      "y": 48,
      "z": -15,
      "name": "Rock_Volcanic_Brick"
    },
    {
      "x": -55,
      "y": 49,
      "z": -15,
      "name": "Rock_Volcanic_Brick"
    },
    {
      "x": -55,
      "y": 50,
      "z": -15,
      "name": "Rock_Volcanic_Brick"
    },
    {
      "x": -55,
      "y": 38,
      "z": -14,
      "name": "Rock_Volcanic_Cobble"
    },
    {
      "x": -55,
      "y": 39,
      "z": -14,
      "name": "Rock_Volcanic_Cobble"
    },
    {
      "x": -55,
      "y": 40,
      "z": -14,
      "name": "Rock_Volcanic_Cobble"
    },
    {
      "x": -55,
      "y": 41,
      "z": -14,
      "name": "Rock_Volcanic_Cobble"
    },
    {
      "x": -55,
      "y": 42,
      "z": -14,
      "name": "Rock_Volcanic_Cobble"
    },
    {
      "x": -55,
      "y": 43,
      "z": -14,
      "name": "Rock_Volcanic_Brick"
    },
    {
      "x": -55,
      "y": 44,
      "z": -14,
      "name": "Rock_Volcanic_Brick"
    },
    {
      "x": -55,
      "y": 45,
      "z": -14,
      "name": "Rock_Volcanic_Brick"
    },
    {
      "x": -55,
      "y": 46,
      "z": -14,
      "name": "Rock_Volcanic_Brick"
    },
    {
      "x": -55,
      "y": 47,
      "z": -14,
      "name": "Rock_Volcanic_Brick"
    },
    {
      "x": -55,
      "y": 48,
      "z": -14,
      "name": "Rock_Volcanic_Brick"
    },
    {
      "x": -55,
      "y": 49,
      "z": -14,
      "name": "Rock_Volcanic_Brick"
    },
    {
      "x": -55,
      "y": 50,
      "z": -14,
      "name": "Rock_Volcanic_Brick"
    },
    {
      "x": -55,
      "y": 51,
      "z": -14,
      "name": "Rock_Volcanic_Brick"
    },
    {
      "x": -54,
      "y": 44,
      "z": -38,
      "name": "Rock_Volcanic_Brick"
    },
    {
      "x": -54,
      "y": 45,
      "z": -38,
      "name": "Rock_Volcanic_Brick"
    },
    {
      "x": -54,
      "y": 46,
      "z": -38,
      "name": "Rock_Volcanic_Brick"
    },
    {
      "x": -54,
      "y": 47,
      "z": -38,
      "name": "Rock_Volcanic_Brick"
    },
    {
      "x": -54,
      "y": 48,
      "z": -38,
      "name": "Rock_Volcanic_Brick"
    },
    {
      "x": -54,
      "y": 49,
      "z": -38,
      "name": "Rock_Volcanic_Brick"
    },
    {
      "x": -54,
      "y": 50,
      "z": -38,
      "name": "Rock_Volcanic_Brick"
    },
    {
      "x": -54,
      "y": 38,
      "z": -37,
      "name": "Rock_Volcanic"
    },
    {
      "x": -54,
      "y": 39,
      "z": -37,
      "name": "Rock_Volcanic"
    },
    {
      "x": -54,
      "y": 40,
      "z": -37,
      "name": "Rock_Volcanic"
    },
    {
      "x": -54,
      "y": 41,
      "z": -37,
      "name": "Rock_Volcanic_Cobble"
    },
    {
      "x": -54,
      "y": 42,
      "z": -37,
      "name": "Rock_Volcanic_Brick"
    },
    {
      "x": -54,
      "y": 43,
      "z": -37,
      "name": "Rock_Volcanic_Brick"
    },
    {
      "x": -54,
      "y": 44,
      "z": -37,
      "name": "Rock_Volcanic_Brick"
    },
    {
      "x": -54,
      "y": 45,
      "z": -37,
      "name": "Rock_Volcanic_Brick"
    },
    {
      "x": -54,
      "y": 46,
      "z": -37,
      "name": "Rock_Volcanic_Brick"
    },
    {
      "x": -54,
      "y": 47,
      "z": -37,
      "name": "Rock_Volcanic_Brick"
    },
    {
      "x": -54,
      "y": 48,
      "z": -37,
      "name": "Rock_Volcanic_Brick"
    },
    {
      "x": -54,
      "y": 49,
      "z": -37,
      "name": "Rock_Volcanic_Brick"
    },
    {
      "x": -54,
      "y": 50,
      "z": -37,
      "name": "Rock_Volcanic_Brick"
    },
    {
      "x": -54,
      "y": 38,
      "z": -36,
      "name": "Rock_Volcanic"
    },
    {
      "x": -54,
      "y": 39,
      "z": -36,
      "name": "Rock_Volcanic"
    },
    {
      "x": -54,
      "y": 40,
      "z": -36,
      "name": "Rock_Volcanic_Cobble"
    },
    {
      "x": -54,
      "y": 41,
      "z": -36,
      "name": "Rock_Volcanic_Cobble"
    },
    {
      "x": -54,
      "y": 42,
      "z": -36,
      "name": "Rock_Volcanic_Cobble"
    },
    {
      "x": -54,
      "y": 43,
      "z": -36,
      "name": "Rock_Volcanic_Brick"
    },
    {
      "x": -54,
      "y": 44,
      "z": -36,
      "name": "Rock_Volcanic_Brick"
    },
    {
      "x": -54,
      "y": 45,
      "z": -36,
      "name": "Rock_Volcanic_Brick"
    },
    {
      "x": -54,
      "y": 46,
      "z": -36,
      "name": "Rock_Volcanic_Brick"
    },
    {
      "x": -54,
      "y": 47,
      "z": -36,
      "name": "Rock_Volcanic_Brick"
    },
    {
      "x": -54,
      "y": 48,
      "z": -36,
      "name": "Rock_Volcanic_Brick"
    },
    {
      "x": -54,
      "y": 49,
      "z": -36,
      "name": "Rock_Volcanic_Brick"
    },
    {
      "x": -54,
      "y": 37,
      "z": -35,
      "name": "Rock_Volcanic"
    },
    {
      "x": -54,
      "y": 38,
      "z": -35,
      "name": "Rock_Volcanic"
    },
    {
      "x": -54,
      "y": 39,
      "z": -35,
      "name": "Rock_Volcanic"
    },
    {
      "x": -54,
      "y": 40,
      "z": -35,
      "name": "Rock_Volcanic_Cobble"
    },
    {
      "x": -54,
      "y": 41,
      "z": -35,
      "name": "Rock_Volcanic_Cobble"
    },
    {
      "x": -54,
      "y": 42,
      "z": -35,
      "name": "Rock_Volcanic_Cobble"
    },
    {
      "x": -54,
      "y": 43,
      "z": -35,
      "name": "Rock_Volcanic_Brick"
    },
    {
      "x": -54,
      "y": 44,
      "z": -35,
      "name": "Rock_Volcanic_Brick"
    },
    {
      "x": -54,
      "y": 45,
      "z": -35,
      "name": "Rock_Volcanic_Brick"
    },
    {
      "x": -54,
      "y": 42,
      "z": -17,
      "name": "Rock_Volcanic_Brick"
    },
    {
      "x": -54,
      "y": 43,
      "z": -17,
      "name": "Rock_Volcanic_Brick"
    },
    {
      "x": -54,
      "y": 44,
      "z": -17,
      "name": "Rock_Volcanic_Brick"
    },
    {
      "x": -54,
      "y": 45,
      "z": -17,
      "name": "Rock_Volcanic_Brick"
    },
    {
      "x": -54,
      "y": 38,
      "z": -16,
      "name": "Rock_Volcanic_Cobble"
    },
    {
      "x": -54,
      "y": 39,
      "z": -16,
      "name": "Rock_Volcanic_Cobble"
    },
    {
      "x": -54,
      "y": 40,
      "z": -16,
      "name": "Rock_Volcanic_Cobble"
    },
    {
      "x": -54,
      "y": 41,
      "z": -16,
      "name": "Rock_Volcanic_Cobble"
    },
    {
      "x": -54,
      "y": 42,
      "z": -16,
      "name": "Rock_Volcanic_Brick"
    },
    {
      "x": -54,
      "y": 43,
      "z": -16,
      "name": "Rock_Volcanic_Brick"
    },
    {
      "x": -54,
      "y": 44,
      "z": -16,
      "name": "Rock_Volcanic_Brick"
    },
    {
      "x": -54,
      "y": 45,
      "z": -16,
      "name": "Rock_Volcanic_Brick"
    },
    {
      "x": -54,
      "y": 46,
      "z": -16,
      "name": "Rock_Volcanic_Brick"
    },
    {
      "x": -54,
      "y": 47,
      "z": -16,
      "name": "Rock_Volcanic_Brick"
    },
    {
      "x": -54,
      "y": 48,
      "z": -16,
      "name": "Rock_Volcanic_Brick"
    },
    {
      "x": -54,
      "y": 49,
      "z": -16,
      "name": "Rock_Volcanic_Brick"
    },
    {
      "x": -54,
      "y": 38,
      "z": -15,
      "name": "Rock_Volcanic_Cobble"
    },
    {
      "x": -54,
      "y": 39,
      "z": -15,
      "name": "Rock_Volcanic_Cobble"
    },
    {
      "x": -54,
      "y": 40,
      "z": -15,
      "name": "Rock_Volcanic_Cobble"
    },
    {
      "x": -54,
      "y": 41,
      "z": -15,
      "name": "Rock_Volcanic_Cobble"
    },
    {
      "x": -54,
      "y": 42,
      "z": -15,
      "name": "Rock_Volcanic_Cobble"
    },
    {
      "x": -54,
      "y": 43,
      "z": -15,
      "name": "Rock_Volcanic_Brick"
    },
    {
      "x": -54,
      "y": 44,
      "z": -15,
      "name": "Rock_Volcanic_Brick"
    },
    {
      "x": -54,
      "y": 45,
      "z": -15,
      "name": "Rock_Volcanic_Brick"
    },
    {
      "x": -54,
      "y": 46,
      "z": -15,
      "name": "Rock_Volcanic_Brick"
    },
    {
      "x": -54,
      "y": 47,
      "z": -15,
      "name": "Rock_Volcanic_Brick"
    },
    {
      "x": -54,
      "y": 48,
      "z": -15,
      "name": "Rock_Volcanic_Brick"
    },
    {
      "x": -54,
      "y": 49,
      "z": -15,
      "name": "Rock_Volcanic_Brick"
    },
    {
      "x": -54,
      "y": 50,
      "z": -15,
      "name": "Rock_Volcanic_Brick"
    },
    {
      "x": -54,
      "y": 38,
      "z": -14,
      "name": "Rock_Volcanic_Cobble"
    },
    {
      "x": -54,
      "y": 39,
      "z": -14,
      "name": "Rock_Volcanic_Cobble"
    },
    {
      "x": -54,
      "y": 40,
      "z": -14,
      "name": "Rock_Volcanic_Cobble"
    },
    {
      "x": -54,
      "y": 41,
      "z": -14,
      "name": "Rock_Volcanic_Cobble"
    },
    {
      "x": -54,
      "y": 42,
      "z": -14,
      "name": "Rock_Volcanic_Cobble"
    },
    {
      "x": -54,
      "y": 43,
      "z": -14,
      "name": "Rock_Volcanic_Brick"
    },
    {
      "x": -54,
      "y": 44,
      "z": -14,
      "name": "Rock_Volcanic_Brick"
    },
    {
      "x": -54,
      "y": 45,
      "z": -14,
      "name": "Rock_Volcanic_Brick"
    },
    {
      "x": -54,
      "y": 46,
      "z": -14,
      "name": "Rock_Volcanic_Brick"
    },
    {
      "x": -54,
      "y": 47,
      "z": -14,
      "name": "Rock_Volcanic_Brick"
    },
    {
      "x": -54,
      "y": 48,
      "z": -14,
      "name": "Rock_Volcanic_Brick"
    },
    {
      "x": -54,
      "y": 49,
      "z": -14,
      "name": "Rock_Volcanic_Brick"
    },
    {
      "x": -54,
      "y": 50,
      "z": -14,
      "name": "Rock_Volcanic_Brick"
    },
    {
      "x": -53,
      "y": 37,
      "z": -37,
      "name": "Rock_Volcanic"
    },
    {
      "x": -53,
      "y": 38,
      "z": -37,
      "name": "Rock_Volcanic"
    },
    {
      "x": -53,
      "y": 39,
      "z": -37,
      "name": "Rock_Volcanic"
    },
    {
      "x": -53,
      "y": 40,
      "z": -37,
      "name": "Rock_Volcanic_Cobble"
    },
    {
      "x": -53,
      "y": 41,
      "z": -37,
      "name": "Rock_Volcanic_Cobble"
    },
    {
      "x": -53,
      "y": 42,
      "z": -37,
      "name": "Rock_Volcanic_Cobble"
    },
    {
      "x": -53,
      "y": 43,
      "z": -37,
      "name": "Rock_Volcanic_Brick"
    },
    {
      "x": -53,
      "y": 44,
      "z": -37,
      "name": "Rock_Volcanic_Brick"
    },
    {
      "x": -53,
      "y": 45,
      "z": -37,
      "name": "Rock_Volcanic_Brick"
    },
    {
      "x": -53,
      "y": 46,
      "z": -37,
      "name": "Rock_Volcanic_Brick"
    },
    {
      "x": -53,
      "y": 47,
      "z": -37,
      "name": "Rock_Volcanic_Brick"
    },
    {
      "x": -53,
      "y": 48,
      "z": -37,
      "name": "Rock_Volcanic_Brick"
    },
    {
      "x": -53,
      "y": 49,
      "z": -37,
      "name": "Rock_Volcanic_Brick"
    },
    {
      "x": -53,
      "y": 37,
      "z": -36,
      "name": "Rock_Volcanic"
    },
    {
      "x": -53,
      "y": 38,
      "z": -36,
      "name": "Rock_Volcanic"
    },
    {
      "x": -53,
      "y": 39,
      "z": -36,
      "name": "Rock_Volcanic"
    },
    {
      "x": -53,
      "y": 40,
      "z": -36,
      "name": "Rock_Volcanic_Cobble"
    },
    {
      "x": -53,
      "y": 41,
      "z": -36,
      "name": "Rock_Volcanic_Cobble"
    },
    {
      "x": -53,
      "y": 42,
      "z": -36,
      "name": "Rock_Volcanic_Cobble"
    },
    {
      "x": -53,
      "y": 43,
      "z": -36,
      "name": "Rock_Volcanic_Cobble"
    },
    {
      "x": -53,
      "y": 44,
      "z": -36,
      "name": "Rock_Volcanic_Cobble"
    },
    {
      "x": -53,
      "y": 45,
      "z": -36,
      "name": "Rock_Volcanic_Cobble"
    },
    {
      "x": -53,
      "y": 46,
      "z": -36,
      "name": "Rock_Volcanic_Cobble"
    },
    {
      "x": -53,
      "y": 47,
      "z": -36,
      "name": "Rock_Volcanic_Brick"
    },
    {
      "x": -53,
      "y": 48,
      "z": -36,
      "name": "Rock_Volcanic_Brick"
    },
    {
      "x": -53,
      "y": 37,
      "z": -35,
      "name": "Rock_Volcanic"
    },
    {
      "x": -53,
      "y": 38,
      "z": -35,
      "name": "Rock_Volcanic"
    },
    {
      "x": -53,
      "y": 39,
      "z": -35,
      "name": "Rock_Volcanic"
    },
    {
      "x": -53,
      "y": 40,
      "z": -35,
      "name": "Rock_Volcanic_Cobble"
    },
    {
      "x": -53,
      "y": 41,
      "z": -35,
      "name": "Rock_Volcanic_Cobble"
    },
    {
      "x": -53,
      "y": 42,
      "z": -35,
      "name": "Rock_Volcanic_Cobble"
    },
    {
      "x": -53,
      "y": 43,
      "z": -35,
      "name": "Rock_Volcanic_Brick"
    },
    {
      "x": -53,
      "y": 44,
      "z": -35,
      "name": "Rock_Volcanic_Brick"
    },
    {
      "x": -53,
      "y": 45,
      "z": -35,
      "name": "Rock_Volcanic_Brick"
    },
    {
      "x": -53,
      "y": 46,
      "z": -35,
      "name": "Rock_Volcanic_Brick"
    },
    {
      "x": -53,
      "y": 47,
      "z": -35,
      "name": "Rock_Volcanic_Brick"
    },
    {
      "x": -53,
      "y": 36,
      "z": -34,
      "name": "Rock_Volcanic"
    },
    {
      "x": -53,
      "y": 37,
      "z": -34,
      "name": "Rock_Volcanic"
    },
    {
      "x": -53,
      "y": 38,
      "z": -34,
      "name": "Rock_Volcanic"
    },
    {
      "x": -53,
      "y": 39,
      "z": -34,
      "name": "Rock_Volcanic_Cobble"
    },
    {
      "x": -53,
      "y": 40,
      "z": -34,
      "name": "Rock_Volcanic_Cobble"
    },
    {
      "x": -53,
      "y": 41,
      "z": -34,
      "name": "Rock_Volcanic_Cobble"
    },
    {
      "x": -53,
      "y": 42,
      "z": -34,
      "name": "Rock_Volcanic_Brick"
    },
    {
      "x": -53,
      "y": 43,
      "z": -34,
      "name": "Rock_Volcanic_Brick"
    },
    {
      "x": -53,
      "y": 44,
      "z": -34,
      "name": "Rock_Volcanic_Brick"
    },
    {
      "x": -53,
      "y": 45,
      "z": -34,
      "name": "Rock_Volcanic_Brick"
    },
    {
      "x": -53,
      "y": 46,
      "z": -34,
      "name": "Rock_Volcanic_Brick"
    },
    {
      "x": -53,
      "y": 35,
      "z": -33,
      "name": "Rock_Volcanic"
    },
    {
      "x": -53,
      "y": 36,
      "z": -33,
      "name": "Rock_Volcanic"
    },
    {
      "x": -53,
      "y": 41,
      "z": -33,
      "name": "Rock_Volcanic_Cobble"
    },
    {
      "x": -53,
      "y": 42,
      "z": -33,
      "name": "Rock_Volcanic_Brick"
    },
    {
      "x": -53,
      "y": 43,
      "z": -33,
      "name": "Rock_Volcanic_Brick"
    },
    {
      "x": -53,
      "y": 44,
      "z": -33,
      "name": "Rock_Volcanic_Brick"
    },
    {
      "x": -53,
      "y": 41,
      "z": -19,
      "name": "Rock_Volcanic_Brick"
    },
    {
      "x": -53,
      "y": 42,
      "z": -19,
      "name": "Rock_Volcanic_Brick"
    },
    {
      "x": -53,
      "y": 43,
      "z": -19,
      "name": "Rock_Volcanic_Brick"
    },
    {
      "x": -53,
      "y": 44,
      "z": -19,
      "name": "Rock_Volcanic_Brick"
    },
    {
      "x": -53,
      "y": 36,
      "z": -18,
      "name": "Rock_Volcanic_Cobble"
    },
    {
      "x": -53,
      "y": 37,
      "z": -18,
      "name": "Rock_Volcanic_Cobble"
    },
    {
      "x": -53,
      "y": 38,
      "z": -18,
      "name": "Rock_Volcanic_Cobble"
    },
    {
      "x": -53,
      "y": 39,
      "z": -18,
      "name": "Rock_Volcanic_Cobble"
    },
    {
      "x": -53,
      "y": 40,
      "z": -18,
      "name": "Rock_Volcanic_Cobble"
    },
    {
      "x": -53,
      "y": 41,
      "z": -18,
      "name": "Rock_Volcanic_Cobble"
    },
    {
      "x": -53,
      "y": 42,
      "z": -18,
      "name": "Rock_Volcanic_Brick"
    },
    {
      "x": -53,
      "y": 43,
      "z": -18,
      "name": "Rock_Volcanic_Brick"
    },
    {
      "x": -53,
      "y": 44,
      "z": -18,
      "name": "Rock_Volcanic_Brick"
    },
    {
      "x": -53,
      "y": 45,
      "z": -18,
      "name": "Rock_Volcanic_Brick"
    },
    {
      "x": -53,
      "y": 46,
      "z": -18,
      "name": "Rock_Volcanic_Brick"
    },
    {
      "x": -53,
      "y": 37,
      "z": -17,
      "name": "Rock_Volcanic_Cobble"
    },
    {
      "x": -53,
      "y": 38,
      "z": -17,
      "name": "Rock_Volcanic_Cobble"
    },
    {
      "x": -53,
      "y": 39,
      "z": -17,
      "name": "Rock_Volcanic_Cobble"
    },
    {
      "x": -53,
      "y": 40,
      "z": -17,
      "name": "Rock_Volcanic_Cobble"
    },
    {
      "x": -53,
      "y": 41,
      "z": -17,
      "name": "Rock_Volcanic_Cobble"
    },
    {
      "x": -53,
      "y": 42,
      "z": -17,
      "name": "Rock_Volcanic_Brick"
    },
    {
      "x": -53,
      "y": 43,
      "z": -17,
      "name": "Rock_Volcanic_Brick"
    },
    {
      "x": -53,
      "y": 44,
      "z": -17,
      "name": "Rock_Volcanic_Brick"
    },
    {
      "x": -53,
      "y": 45,
      "z": -17,
      "name": "Rock_Volcanic_Brick"
    },
    {
      "x": -53,
      "y": 46,
      "z": -17,
      "name": "Rock_Volcanic_Brick"
    },
    {
      "x": -53,
      "y": 47,
      "z": -17,
      "name": "Rock_Volcanic_Brick"
    },
    {
      "x": -53,
      "y": 38,
      "z": -16,
      "name": "Rock_Volcanic_Cobble"
    },
    {
      "x": -53,
      "y": 39,
      "z": -16,
      "name": "Rock_Volcanic_Cobble"
    },
    {
      "x": -53,
      "y": 40,
      "z": -16,
      "name": "Rock_Volcanic_Cobble"
    },
    {
      "x": -53,
      "y": 41,
      "z": -16,
      "name": "Rock_Volcanic_Cobble"
    },
    {
      "x": -53,
      "y": 42,
      "z": -16,
      "name": "Rock_Volcanic_Cobble"
    },
    {
      "x": -53,
      "y": 43,
      "z": -16,
      "name": "Rock_Volcanic_Cobble"
    },
    {
      "x": -53,
      "y": 44,
      "z": -16,
      "name": "Rock_Volcanic"
    },
    {
      "x": -53,
      "y": 45,
      "z": -16,
      "name": "Rock_Volcanic"
    },
    {
      "x": -53,
      "y": 46,
      "z": -16,
      "name": "Rock_Volcanic"
    },
    {
      "x": -53,
      "y": 47,
      "z": -16,
      "name": "Rock_Volcanic_Brick"
    },
    {
      "x": -53,
      "y": 48,
      "z": -16,
      "name": "Rock_Volcanic_Brick"
    },
    {
      "x": -53,
      "y": 38,
      "z": -15,
      "name": "Rock_Volcanic_Cobble"
    },
    {
      "x": -53,
      "y": 39,
      "z": -15,
      "name": "Rock_Volcanic_Cobble"
    },
    {
      "x": -53,
      "y": 40,
      "z": -15,
      "name": "Rock_Volcanic_Cobble"
    },
    {
      "x": -53,
      "y": 41,
      "z": -15,
      "name": "Rock_Volcanic_Cobble"
    },
    {
      "x": -53,
      "y": 42,
      "z": -15,
      "name": "Rock_Volcanic_Cobble"
    },
    {
      "x": -53,
      "y": 43,
      "z": -15,
      "name": "Rock_Volcanic_Brick"
    },
    {
      "x": -53,
      "y": 44,
      "z": -15,
      "name": "Rock_Volcanic_Brick"
    },
    {
      "x": -53,
      "y": 45,
      "z": -15,
      "name": "Rock_Volcanic_Brick"
    },
    {
      "x": -53,
      "y": 46,
      "z": -15,
      "name": "Rock_Volcanic_Brick"
    },
    {
      "x": -53,
      "y": 47,
      "z": -15,
      "name": "Rock_Volcanic_Brick"
    },
    {
      "x": -53,
      "y": 48,
      "z": -15,
      "name": "Rock_Volcanic_Brick"
    },
    {
      "x": -53,
      "y": 49,
      "z": -15,
      "name": "Rock_Volcanic_Brick"
    },
    {
      "x": -52,
      "y": 40,
      "z": -37,
      "name": "Rock_Volcanic_Cobble"
    },
    {
      "x": -52,
      "y": 41,
      "z": -37,
      "name": "Rock_Volcanic_Cobble"
    },
    {
      "x": -52,
      "y": 42,
      "z": -37,
      "name": "Rock_Volcanic_Brick"
    },
    {
      "x": -52,
      "y": 43,
      "z": -37,
      "name": "Rock_Volcanic_Brick"
    },
    {
      "x": -52,
      "y": 44,
      "z": -37,
      "name": "Rock_Volcanic_Brick"
    },
    {
      "x": -52,
      "y": 45,
      "z": -37,
      "name": "Rock_Volcanic_Brick"
    },
    {
      "x": -52,
      "y": 46,
      "z": -37,
      "name": "Rock_Volcanic_Brick"
    },
    {
      "x": -52,
      "y": 47,
      "z": -37,
      "name": "Rock_Volcanic_Brick"
    },
    {
      "x": -52,
      "y": 48,
      "z": -37,
      "name": "Rock_Volcanic_Brick"
    },
    {
      "x": -52,
      "y": 37,
      "z": -36,
      "name": "Rock_Volcanic"
    },
    {
      "x": -52,
      "y": 38,
      "z": -36,
      "name": "Rock_Volcanic"
    },
    {
      "x": -52,
      "y": 39,
      "z": -36,
      "name": "Rock_Volcanic_Cobble"
    },
    {
      "x": -52,
      "y": 40,
      "z": -36,
      "name": "Rock_Volcanic_Cobble"
    },
    {
      "x": -52,
      "y": 41,
      "z": -36,
      "name": "Rock_Volcanic_Cobble"
    },
    {
      "x": -52,
      "y": 42,
      "z": -36,
      "name": "Rock_Volcanic_Cobble"
    },
    {
      "x": -52,
      "y": 43,
      "z": -36,
      "name": "Rock_Volcanic_Cobble"
    },
    {
      "x": -52,
      "y": 44,
      "z": -36,
      "name": "Rock_Volcanic_Brick"
    },
    {
      "x": -52,
      "y": 45,
      "z": -36,
      "name": "Rock_Volcanic_Cobble"
    },
    {
      "x": -52,
      "y": 46,
      "z": -36,
      "name": "Rock_Volcanic_Brick"
    },
    {
      "x": -52,
      "y": 47,
      "z": -36,
      "name": "Rock_Volcanic_Brick"
    },
    {
      "x": -52,
      "y": 19,
      "z": -35,
      "name": "Rock_Volcanic"
    },
    {
      "x": -52,
      "y": 20,
      "z": -35,
      "name": "Rock_Volcanic"
    },
    {
      "x": -52,
      "y": 21,
      "z": -35,
      "name": "Rock_Volcanic"
    },
    {
      "x": -52,
      "y": 22,
      "z": -35,
      "name": "Rock_Volcanic"
    },
    {
      "x": -52,
      "y": 23,
      "z": -35,
      "name": "Rock_Volcanic"
    },
    {
      "x": -52,
      "y": 35,
      "z": -35,
      "name": "Rock_Volcanic"
    },
    {
      "x": -52,
      "y": 36,
      "z": -35,
      "name": "Rock_Volcanic"
    },
    {
      "x": -52,
      "y": 37,
      "z": -35,
      "name": "Rock_Volcanic"
    },
    {
      "x": -52,
      "y": 38,
      "z": -35,
      "name": "Rock_Volcanic"
    },
    {
      "x": -52,
      "y": 39,
      "z": -35,
      "name": "Rock_Volcanic"
    },
    {
      "x": -52,
      "y": 40,
      "z": -35,
      "name": "Rock_Volcanic_Cobble"
    },
    {
      "x": -52,
      "y": 41,
      "z": -35,
      "name": "Rock_Volcanic_Cobble"
    },
    {
      "x": -52,
      "y": 42,
      "z": -35,
      "name": "Rock_Volcanic_Cobble"
    },
    {
      "x": -52,
      "y": 43,
      "z": -35,
      "name": "Rock_Volcanic_Cobble"
    },
    {
      "x": -52,
      "y": 44,
      "z": -35,
      "name": "Rock_Volcanic_Cobble"
    },
    {
      "x": -52,
      "y": 45,
      "z": -35,
      "name": "Rock_Volcanic_Cobble"
    },
    {
      "x": -52,
      "y": 46,
      "z": -35,
      "name": "Rock_Volcanic_Brick"
    },
    {
      "x": -52,
      "y": 20,
      "z": -34,
      "name": "Rock_Volcanic"
    },
    {
      "x": -52,
      "y": 21,
      "z": -34,
      "name": "Rock_Volcanic"
    },
    {
      "x": -52,
      "y": 22,
      "z": -34,
      "name": "Rock_Volcanic"
    },
    {
      "x": -52,
      "y": 23,
      "z": -34,
      "name": "Rock_Volcanic"
    },
    {
      "x": -52,
      "y": 24,
      "z": -34,
      "name": "Rock_Volcanic"
    },
    {
      "x": -52,
      "y": 33,
      "z": -34,
      "name": "Rock_Volcanic"
    },
    {
      "x": -52,
      "y": 34,
      "z": -34,
      "name": "Rock_Volcanic"
    },
    {
      "x": -52,
      "y": 35,
      "z": -34,
      "name": "Rock_Volcanic"
    },
    {
      "x": -52,
      "y": 36,
      "z": -34,
      "name": "Rock_Volcanic"
    },
    {
      "x": -52,
      "y": 37,
      "z": -34,
      "name": "Rock_Volcanic"
    },
    {
      "x": -52,
      "y": 38,
      "z": -34,
      "name": "Rock_Volcanic"
    },
    {
      "x": -52,
      "y": 39,
      "z": -34,
      "name": "Rock_Volcanic_Cobble"
    },
    {
      "x": -52,
      "y": 40,
      "z": -34,
      "name": "Rock_Volcanic_Cobble"
    },
    {
      "x": -52,
      "y": 41,
      "z": -34,
      "name": "Rock_Volcanic_Cobble"
    },
    {
      "x": -52,
      "y": 42,
      "z": -34,
      "name": "Rock_Volcanic_Cobble"
    },
    {
      "x": -52,
      "y": 43,
      "z": -34,
      "name": "Rock_Volcanic_Cobble"
    },
    {
      "x": -52,
      "y": 44,
      "z": -34,
      "name": "Rock_Volcanic_Brick"
    },
    {
      "x": -52,
      "y": 45,
      "z": -34,
      "name": "Rock_Volcanic_Brick"
    },
    {
      "x": -52,
      "y": 46,
      "z": -34,
      "name": "Rock_Volcanic_Brick"
    },
    {
      "x": -52,
      "y": 33,
      "z": -33,
      "name": "Rock_Volcanic"
    },
    {
      "x": -52,
      "y": 34,
      "z": -33,
      "name": "Rock_Volcanic"
    },
    {
      "x": -52,
      "y": 35,
      "z": -33,
      "name": "Rock_Volcanic"
    },
    {
      "x": -52,
      "y": 36,
      "z": -33,
      "name": "Rock_Volcanic"
    },
    {
      "x": -52,
      "y": 37,
      "z": -33,
      "name": "Rock_Volcanic"
    },
    {
      "x": -52,
      "y": 38,
      "z": -33,
      "name": "Rock_Volcanic_Cobble"
    },
    {
      "x": -52,
      "y": 39,
      "z": -33,
      "name": "Rock_Volcanic_Cobble"
    },
    {
      "x": -52,
      "y": 40,
      "z": -33,
      "name": "Rock_Volcanic_Cobble"
    },
    {
      "x": -52,
      "y": 41,
      "z": -33,
      "name": "Rock_Volcanic_Cobble"
    },
    {
      "x": -52,
      "y": 42,
      "z": -33,
      "name": "Rock_Volcanic_Brick"
    },
    {
      "x": -52,
      "y": 43,
      "z": -33,
      "name": "Rock_Volcanic_Brick"
    },
    {
      "x": -52,
      "y": 44,
      "z": -33,
      "name": "Rock_Volcanic_Brick"
    },
    {
      "x": -52,
      "y": 45,
      "z": -33,
      "name": "Rock_Volcanic_Brick"
    },
    {
      "x": -52,
      "y": 31,
      "z": -32,
      "name": "Rock_Volcanic"
    },
    {
      "x": -52,
      "y": 32,
      "z": -32,
      "name": "Rock_Volcanic"
    },
    {
      "x": -52,
      "y": 33,
      "z": -32,
      "name": "Rock_Volcanic"
    },
    {
      "x": -52,
      "y": 34,
      "z": -32,
      "name": "Rock_Volcanic"
    },
    {
      "x": -52,
      "y": 35,
      "z": -32,
      "name": "Rock_Volcanic"
    },
    {
      "x": -52,
      "y": 36,
      "z": -32,
      "name": "Rock_Volcanic"
    },
    {
      "x": -52,
      "y": 37,
      "z": -32,
      "name": "Rock_Volcanic"
    },
    {
      "x": -52,
      "y": 38,
      "z": -32,
      "name": "Rock_Volcanic_Cobble"
    },
    {
      "x": -52,
      "y": 39,
      "z": -32,
      "name": "Rock_Volcanic_Cobble"
    },
    {
      "x": -52,
      "y": 40,
      "z": -32,
      "name": "Rock_Volcanic_Cobble"
    },
    {
      "x": -52,
      "y": 41,
      "z": -32,
      "name": "Rock_Volcanic_Cobble"
    },
    {
      "x": -52,
      "y": 42,
      "z": -32,
      "name": "Rock_Volcanic_Brick"
    },
    {
      "x": -52,
      "y": 43,
      "z": -32,
      "name": "Rock_Volcanic_Brick"
    },
    {
      "x": -52,
      "y": 44,
      "z": -32,
      "name": "Rock_Volcanic_Brick"
    },
    {
      "x": -52,
      "y": 35,
      "z": -31,
      "name": "Rock_Volcanic"
    },
    {
      "x": -52,
      "y": 36,
      "z": -20,
      "name": "Rock_Volcanic_Cobble"
    },
    {
      "x": -52,
      "y": 37,
      "z": -20,
      "name": "Rock_Volcanic_Cobble"
    },
    {
      "x": -52,
      "y": 38,
      "z": -20,
      "name": "Rock_Volcanic_Cobble"
    },
    {
      "x": -52,
      "y": 39,
      "z": -20,
      "name": "Rock_Volcanic_Cobble"
    },
    {
      "x": -52,
      "y": 40,
      "z": -20,
      "name": "Rock_Volcanic_Brick"
    },
    {
      "x": -52,
      "y": 41,
      "z": -20,
      "name": "Rock_Volcanic_Brick"
    },
    {
      "x": -52,
      "y": 42,
      "z": -20,
      "name": "Rock_Volcanic_Brick"
    },
    {
      "x": -52,
      "y": 43,
      "z": -20,
      "name": "Rock_Volcanic_Brick"
    },
    {
      "x": -52,
      "y": 44,
      "z": -20,
      "name": "Rock_Volcanic_Brick"
    },
    {
      "x": -52,
      "y": 34,
      "z": -19,
      "name": "Rock_Volcanic_Cobble"
    },
    {
      "x": -52,
      "y": 35,
      "z": -19,
      "name": "Rock_Volcanic_Cobble"
    },
    {
      "x": -52,
      "y": 36,
      "z": -19,
      "name": "Rock_Volcanic_Cobble"
    },
    {
      "x": -52,
      "y": 37,
      "z": -19,
      "name": "Rock_Volcanic_Cobble"
    },
    {
      "x": -52,
      "y": 38,
      "z": -19,
      "name": "Rock_Volcanic_Cobble"
    },
    {
      "x": -52,
      "y": 39,
      "z": -19,
      "name": "Rock_Volcanic_Cobble"
    },
    {
      "x": -52,
      "y": 40,
      "z": -19,
      "name": "Rock_Volcanic_Brick"
    },
    {
      "x": -52,
      "y": 41,
      "z": -19,
      "name": "Rock_Volcanic_Brick"
    },
    {
      "x": -52,
      "y": 42,
      "z": -19,
      "name": "Rock_Volcanic_Brick"
    },
    {
      "x": -52,
      "y": 43,
      "z": -19,
      "name": "Rock_Volcanic_Brick"
    },
    {
      "x": -52,
      "y": 44,
      "z": -19,
      "name": "Rock_Volcanic_Brick"
    },
    {
      "x": -52,
      "y": 45,
      "z": -19,
      "name": "Rock_Volcanic_Brick"
    },
    {
      "x": -52,
      "y": 34,
      "z": -18,
      "name": "Rock_Volcanic_Cobble"
    },
    {
      "x": -52,
      "y": 35,
      "z": -18,
      "name": "Rock_Volcanic_Cobble"
    },
    {
      "x": -52,
      "y": 36,
      "z": -18,
      "name": "Rock_Volcanic_Cobble"
    },
    {
      "x": -52,
      "y": 37,
      "z": -18,
      "name": "Rock_Volcanic_Cobble"
    },
    {
      "x": -52,
      "y": 38,
      "z": -18,
      "name": "Rock_Volcanic_Cobble"
    },
    {
      "x": -52,
      "y": 39,
      "z": -18,
      "name": "Rock_Volcanic_Cobble"
    },
    {
      "x": -52,
      "y": 40,
      "z": -18,
      "name": "Rock_Volcanic_Cobble"
    },
    {
      "x": -52,
      "y": 41,
      "z": -18,
      "name": "Rock_Volcanic"
    },
    {
      "x": -52,
      "y": 42,
      "z": -18,
      "name": "Rock_Volcanic"
    },
    {
      "x": -52,
      "y": 43,
      "z": -18,
      "name": "Rock_Volcanic"
    },
    {
      "x": -52,
      "y": 44,
      "z": -18,
      "name": "Rock_Volcanic_Brick"
    },
    {
      "x": -52,
      "y": 45,
      "z": -18,
      "name": "Rock_Volcanic_Brick"
    },
    {
      "x": -52,
      "y": 46,
      "z": -18,
      "name": "Rock_Volcanic_Brick"
    },
    {
      "x": -52,
      "y": 35,
      "z": -17,
      "name": "Rock_Volcanic_Cobble"
    },
    {
      "x": -52,
      "y": 36,
      "z": -17,
      "name": "Rock_Volcanic_Cobble"
    },
    {
      "x": -52,
      "y": 37,
      "z": -17,
      "name": "Rock_Volcanic_Cobble"
    },
    {
      "x": -52,
      "y": 38,
      "z": -17,
      "name": "Rock_Volcanic_Cobble"
    },
    {
      "x": -52,
      "y": 39,
      "z": -17,
      "name": "Rock_Volcanic_Cobble"
    },
    {
      "x": -52,
      "y": 40,
      "z": -17,
      "name": "Rock_Volcanic_Cobble"
    },
    {
      "x": -52,
      "y": 41,
      "z": -17,
      "name": "Rock_Volcanic_Cobble"
    },
    {
      "x": -52,
      "y": 42,
      "z": -17,
      "name": "Rock_Volcanic"
    },
    {
      "x": -52,
      "y": 43,
      "z": -17,
      "name": "Rock_Volcanic"
    },
    {
      "x": -52,
      "y": 44,
      "z": -17,
      "name": "Rock_Volcanic"
    },
    {
      "x": -52,
      "y": 45,
      "z": -17,
      "name": "Rock_Volcanic"
    },
    {
      "x": -52,
      "y": 46,
      "z": -17,
      "name": "Rock_Volcanic_Brick"
    },
    {
      "x": -52,
      "y": 37,
      "z": -16,
      "name": "Rock_Volcanic_Cobble"
    },
    {
      "x": -52,
      "y": 38,
      "z": -16,
      "name": "Rock_Volcanic_Cobble"
    },
    {
      "x": -52,
      "y": 39,
      "z": -16,
      "name": "Rock_Volcanic_Cobble"
    },
    {
      "x": -52,
      "y": 40,
      "z": -16,
      "name": "Rock_Volcanic_Cobble"
    },
    {
      "x": -52,
      "y": 41,
      "z": -16,
      "name": "Rock_Volcanic_Cobble"
    },
    {
      "x": -52,
      "y": 42,
      "z": -16,
      "name": "Rock_Volcanic_Cobble"
    },
    {
      "x": -52,
      "y": 43,
      "z": -16,
      "name": "Rock_Volcanic"
    },
    {
      "x": -52,
      "y": 44,
      "z": -16,
      "name": "Rock_Volcanic_Brick"
    },
    {
      "x": -52,
      "y": 45,
      "z": -16,
      "name": "Rock_Volcanic"
    },
    {
      "x": -52,
      "y": 46,
      "z": -16,
      "name": "Rock_Volcanic_Brick"
    },
    {
      "x": -52,
      "y": 47,
      "z": -16,
      "name": "Rock_Volcanic_Brick"
    },
    {
      "x": -52,
      "y": 40,
      "z": -15,
      "name": "Rock_Volcanic_Cobble"
    },
    {
      "x": -52,
      "y": 41,
      "z": -15,
      "name": "Rock_Volcanic_Cobble"
    },
    {
      "x": -52,
      "y": 42,
      "z": -15,
      "name": "Rock_Volcanic_Cobble"
    },
    {
      "x": -52,
      "y": 43,
      "z": -15,
      "name": "Rock_Volcanic_Brick"
    },
    {
      "x": -52,
      "y": 44,
      "z": -15,
      "name": "Rock_Volcanic_Brick"
    },
    {
      "x": -52,
      "y": 45,
      "z": -15,
      "name": "Rock_Volcanic_Brick"
    },
    {
      "x": -52,
      "y": 46,
      "z": -15,
      "name": "Rock_Volcanic_Brick"
    },
    {
      "x": -52,
      "y": 47,
      "z": -15,
      "name": "Rock_Volcanic_Brick"
    },
    {
      "x": -52,
      "y": 48,
      "z": -15,
      "name": "Rock_Volcanic_Brick"
    },
    {
      "x": -51,
      "y": 42,
      "z": -37,
      "name": "Rock_Volcanic_Brick"
    },
    {
      "x": -51,
      "y": 43,
      "z": -37,
      "name": "Rock_Volcanic_Brick"
    },
    {
      "x": -51,
      "y": 44,
      "z": -37,
      "name": "Rock_Volcanic_Brick"
    },
    {
      "x": -51,
      "y": 45,
      "z": -37,
      "name": "Rock_Volcanic_Brick"
    },
    {
      "x": -51,
      "y": 46,
      "z": -37,
      "name": "Rock_Volcanic_Brick"
    },
    {
      "x": -51,
      "y": 47,
      "z": -37,
      "name": "Rock_Volcanic_Brick"
    },
    {
      "x": -51,
      "y": 35,
      "z": -36,
      "name": "Rock_Volcanic"
    },
    {
      "x": -51,
      "y": 36,
      "z": -36,
      "name": "Rock_Volcanic"
    },
    {
      "x": -51,
      "y": 37,
      "z": -36,
      "name": "Rock_Volcanic_Cobble"
    },
    {
      "x": -51,
      "y": 38,
      "z": -36,
      "name": "Rock_Volcanic_Cobble"
    },
    {
      "x": -51,
      "y": 39,
      "z": -36,
      "name": "Rock_Volcanic_Cobble"
    },
    {
      "x": -51,
      "y": 40,
      "z": -36,
      "name": "Rock_Volcanic_Cobble"
    },
    {
      "x": -51,
      "y": 41,
      "z": -36,
      "name": "Rock_Volcanic_Cobble"
    },
    {
      "x": -51,
      "y": 42,
      "z": -36,
      "name": "Rock_Volcanic_Brick"
    },
    {
      "x": -51,
      "y": 43,
      "z": -36,
      "name": "Rock_Volcanic_Brick"
    },
    {
      "x": -51,
      "y": 44,
      "z": -36,
      "name": "Rock_Volcanic_Brick"
    },
    {
      "x": -51,
      "y": 45,
      "z": -36,
      "name": "Rock_Volcanic_Brick"
    },
    {
      "x": -51,
      "y": 46,
      "z": -36,
      "name": "Rock_Volcanic_Brick"
    },
    {
      "x": -51,
      "y": 20,
      "z": -35,
      "name": "Rock_Volcanic"
    },
    {
      "x": -51,
      "y": 21,
      "z": -35,
      "name": "Rock_Volcanic"
    },
    {
      "x": -51,
      "y": 22,
      "z": -35,
      "name": "Rock_Volcanic"
    },
    {
      "x": -51,
      "y": 23,
      "z": -35,
      "name": "Rock_Volcanic"
    },
    {
      "x": -51,
      "y": 24,
      "z": -35,
      "name": "Rock_Volcanic"
    },
    {
      "x": -51,
      "y": 33,
      "z": -35,
      "name": "Rock_Volcanic"
    },
    {
      "x": -51,
      "y": 34,
      "z": -35,
      "name": "Rock_Volcanic"
    },
    {
      "x": -51,
      "y": 35,
      "z": -35,
      "name": "Rock_Volcanic"
    },
    {
      "x": -51,
      "y": 36,
      "z": -35,
      "name": "Rock_Volcanic"
    },
    {
      "x": -51,
      "y": 37,
      "z": -35,
      "name": "Rock_Volcanic_Cobble"
    },
    {
      "x": -51,
      "y": 38,
      "z": -35,
      "name": "Rock_Volcanic_Cobble"
    },
    {
      "x": -51,
      "y": 39,
      "z": -35,
      "name": "Rock_Volcanic_Cobble"
    },
    {
      "x": -51,
      "y": 40,
      "z": -35,
      "name": "Rock_Volcanic_Cobble"
    },
    {
      "x": -51,
      "y": 41,
      "z": -35,
      "name": "Rock_Volcanic_Cobble"
    },
    {
      "x": -51,
      "y": 42,
      "z": -35,
      "name": "Rock_Volcanic_Cobble"
    },
    {
      "x": -51,
      "y": 43,
      "z": -35,
      "name": "Rock_Volcanic_Cobble"
    },
    {
      "x": -51,
      "y": 44,
      "z": -35,
      "name": "Rock_Volcanic_Cobble"
    },
    {
      "x": -51,
      "y": 45,
      "z": -35,
      "name": "Rock_Volcanic_Brick"
    },
    {
      "x": -51,
      "y": 20,
      "z": -34,
      "name": "Rock_Volcanic"
    },
    {
      "x": -51,
      "y": 21,
      "z": -34,
      "name": "Rock_Volcanic"
    },
    {
      "x": -51,
      "y": 22,
      "z": -34,
      "name": "Rock_Volcanic"
    },
    {
      "x": -51,
      "y": 23,
      "z": -34,
      "name": "Rock_Volcanic"
    },
    {
      "x": -51,
      "y": 24,
      "z": -34,
      "name": "Rock_Volcanic"
    },
    {
      "x": -51,
      "y": 25,
      "z": -34,
      "name": "Rock_Volcanic"
    },
    {
      "x": -51,
      "y": 30,
      "z": -34,
      "name": "Rock_Volcanic"
    },
    {
      "x": -51,
      "y": 31,
      "z": -34,
      "name": "Rock_Volcanic"
    },
    {
      "x": -51,
      "y": 32,
      "z": -34,
      "name": "Rock_Volcanic"
    },
    {
      "x": -51,
      "y": 33,
      "z": -34,
      "name": "Rock_Volcanic"
    },
    {
      "x": -51,
      "y": 34,
      "z": -34,
      "name": "Rock_Volcanic"
    },
    {
      "x": -51,
      "y": 35,
      "z": -34,
      "name": "Rock_Volcanic"
    },
    {
      "x": -51,
      "y": 36,
      "z": -34,
      "name": "Rock_Volcanic"
    },
    {
      "x": -51,
      "y": 37,
      "z": -34,
      "name": "Rock_Volcanic_Cobble"
    },
    {
      "x": -51,
      "y": 38,
      "z": -34,
      "name": "Rock_Volcanic_Cobble"
    },
    {
      "x": -51,
      "y": 39,
      "z": -34,
      "name": "Rock_Volcanic_Cobble"
    },
    {
      "x": -51,
      "y": 40,
      "z": -34,
      "name": "Rock_Volcanic_Cobble"
    },
    {
      "x": -51,
      "y": 41,
      "z": -34,
      "name": "Rock_Volcanic_Cobble"
    },
    {
      "x": -51,
      "y": 42,
      "z": -34,
      "name": "Rock_Volcanic_Cobble"
    },
    {
      "x": -51,
      "y": 43,
      "z": -34,
      "name": "Rock_Volcanic_Cobble"
    },
    {
      "x": -51,
      "y": 44,
      "z": -34,
      "name": "Rock_Volcanic_Brick"
    },
    {
      "x": -51,
      "y": 45,
      "z": -34,
      "name": "Rock_Volcanic_Brick"
    },
    {
      "x": -51,
      "y": 21,
      "z": -33,
      "name": "Rock_Volcanic"
    },
    {
      "x": -51,
      "y": 22,
      "z": -33,
      "name": "Rock_Volcanic"
    },
    {
      "x": -51,
      "y": 23,
      "z": -33,
      "name": "Rock_Volcanic"
    },
    {
      "x": -51,
      "y": 24,
      "z": -33,
      "name": "Rock_Volcanic"
    },
    {
      "x": -51,
      "y": 25,
      "z": -33,
      "name": "Rock_Volcanic"
    },
    {
      "x": -51,
      "y": 26,
      "z": -33,
      "name": "Rock_Volcanic"
    },
    {
      "x": -51,
      "y": 27,
      "z": -33,
      "name": "Rock_Volcanic"
    },
    {
      "x": -51,
      "y": 28,
      "z": -33,
      "name": "Rock_Volcanic"
    },
    {
      "x": -51,
      "y": 29,
      "z": -33,
      "name": "Rock_Volcanic"
    },
    {
      "x": -51,
      "y": 30,
      "z": -33,
      "name": "Rock_Volcanic"
    },
    {
      "x": -51,
      "y": 31,
      "z": -33,
      "name": "Rock_Volcanic"
    },
    {
      "x": -51,
      "y": 32,
      "z": -33,
      "name": "Rock_Volcanic"
    },
    {
      "x": -51,
      "y": 33,
      "z": -33,
      "name": "Rock_Volcanic"
    },
    {
      "x": -51,
      "y": 34,
      "z": -33,
      "name": "Rock_Volcanic"
    },
    {
      "x": -51,
      "y": 35,
      "z": -33,
      "name": "Rock_Volcanic"
    },
    {
      "x": -51,
      "y": 36,
      "z": -33,
      "name": "Rock_Volcanic"
    },
    {
      "x": -51,
      "y": 37,
      "z": -33,
      "name": "Rock_Volcanic"
    },
    {
      "x": -51,
      "y": 38,
      "z": -33,
      "name": "Rock_Volcanic_Cobble"
    },
    {
      "x": -51,
      "y": 39,
      "z": -33,
      "name": "Rock_Volcanic_Cobble"
    },
    {
      "x": -51,
      "y": 40,
      "z": -33,
      "name": "Rock_Volcanic_Cobble"
    },
    {
      "x": -51,
      "y": 41,
      "z": -33,
      "name": "Rock_Volcanic_Cobble"
    },
    {
      "x": -51,
      "y": 42,
      "z": -33,
      "name": "Rock_Volcanic_Cobble"
    },
    {
      "x": -51,
      "y": 43,
      "z": -33,
      "name": "Rock_Volcanic_Cobble"
    },
    {
      "x": -51,
      "y": 44,
      "z": -33,
      "name": "Rock_Volcanic_Brick"
    },
    {
      "x": -51,
      "y": 21,
      "z": -32,
      "name": "Rock_Volcanic"
    },
    {
      "x": -51,
      "y": 22,
      "z": -32,
      "name": "Rock_Volcanic"
    },
    {
      "x": -51,
      "y": 23,
      "z": -32,
      "name": "Rock_Volcanic"
    },
    {
      "x": -51,
      "y": 24,
      "z": -32,
      "name": "Rock_Volcanic"
    },
    {
      "x": -51,
      "y": 25,
      "z": -32,
      "name": "Rock_Volcanic"
    },
    {
      "x": -51,
      "y": 26,
      "z": -32,
      "name": "Rock_Volcanic"
    },
    {
      "x": -51,
      "y": 27,
      "z": -32,
      "name": "Rock_Volcanic"
    },
    {
      "x": -51,
      "y": 28,
      "z": -32,
      "name": "Rock_Volcanic"
    },
    {
      "x": -51,
      "y": 29,
      "z": -32,
      "name": "Rock_Volcanic"
    },
    {
      "x": -51,
      "y": 30,
      "z": -32,
      "name": "Rock_Volcanic"
    },
    {
      "x": -51,
      "y": 31,
      "z": -32,
      "name": "Rock_Volcanic"
    },
    {
      "x": -51,
      "y": 32,
      "z": -32,
      "name": "Rock_Volcanic"
    },
    {
      "x": -51,
      "y": 33,
      "z": -32,
      "name": "Rock_Volcanic"
    },
    {
      "x": -51,
      "y": 34,
      "z": -32,
      "name": "Rock_Volcanic"
    },
    {
      "x": -51,
      "y": 35,
      "z": -32,
      "name": "Rock_Volcanic"
    },
    {
      "x": -51,
      "y": 36,
      "z": -32,
      "name": "Rock_Volcanic"
    },
    {
      "x": -51,
      "y": 37,
      "z": -32,
      "name": "Rock_Volcanic_Cobble"
    },
    {
      "x": -51,
      "y": 38,
      "z": -32,
      "name": "Rock_Volcanic_Cobble"
    },
    {
      "x": -51,
      "y": 39,
      "z": -32,
      "name": "Rock_Volcanic_Cobble"
    },
    {
      "x": -51,
      "y": 40,
      "z": -32,
      "name": "Rock_Volcanic_Cobble"
    },
    {
      "x": -51,
      "y": 41,
      "z": -32,
      "name": "Rock_Volcanic_Brick"
    },
    {
      "x": -51,
      "y": 42,
      "z": -32,
      "name": "Rock_Volcanic_Brick"
    },
    {
      "x": -51,
      "y": 43,
      "z": -32,
      "name": "Rock_Volcanic_Brick"
    },
    {
      "x": -51,
      "y": 23,
      "z": -31,
      "name": "Rock_Volcanic"
    },
    {
      "x": -51,
      "y": 24,
      "z": -31,
      "name": "Rock_Volcanic"
    },
    {
      "x": -51,
      "y": 25,
      "z": -31,
      "name": "Rock_Volcanic"
    },
    {
      "x": -51,
      "y": 26,
      "z": -31,
      "name": "Rock_Volcanic"
    },
    {
      "x": -51,
      "y": 27,
      "z": -31,
      "name": "Rock_Volcanic"
    },
    {
      "x": -51,
      "y": 28,
      "z": -31,
      "name": "Rock_Volcanic"
    },
    {
      "x": -51,
      "y": 29,
      "z": -31,
      "name": "Rock_Volcanic"
    },
    {
      "x": -51,
      "y": 30,
      "z": -31,
      "name": "Rock_Volcanic"
    },
    {
      "x": -51,
      "y": 31,
      "z": -31,
      "name": "Rock_Volcanic"
    },
    {
      "x": -51,
      "y": 32,
      "z": -31,
      "name": "Rock_Volcanic"
    },
    {
      "x": -51,
      "y": 33,
      "z": -31,
      "name": "Rock_Volcanic"
    },
    {
      "x": -51,
      "y": 34,
      "z": -31,
      "name": "Rock_Volcanic"
    },
    {
      "x": -51,
      "y": 35,
      "z": -31,
      "name": "Rock_Volcanic"
    },
    {
      "x": -51,
      "y": 36,
      "z": -31,
      "name": "Rock_Volcanic_Cobble"
    },
    {
      "x": -51,
      "y": 37,
      "z": -31,
      "name": "Rock_Volcanic_Cobble"
    },
    {
      "x": -51,
      "y": 38,
      "z": -31,
      "name": "Rock_Volcanic_Cobble"
    },
    {
      "x": -51,
      "y": 39,
      "z": -31,
      "name": "Rock_Volcanic_Cobble"
    },
    {
      "x": -51,
      "y": 40,
      "z": -31,
      "name": "Rock_Volcanic_Brick"
    },
    {
      "x": -51,
      "y": 41,
      "z": -31,
      "name": "Rock_Volcanic_Brick"
    },
    {
      "x": -51,
      "y": 42,
      "z": -31,
      "name": "Rock_Volcanic_Brick"
    },
    {
      "x": -51,
      "y": 43,
      "z": -31,
      "name": "Rock_Volcanic_Brick"
    },
    {
      "x": -51,
      "y": 28,
      "z": -30,
      "name": "Rock_Volcanic"
    },
    {
      "x": -51,
      "y": 29,
      "z": -30,
      "name": "Rock_Volcanic"
    },
    {
      "x": -51,
      "y": 30,
      "z": -30,
      "name": "Rock_Volcanic"
    },
    {
      "x": -51,
      "y": 34,
      "z": -21,
      "name": "Rock_Volcanic_Cobble"
    },
    {
      "x": -51,
      "y": 35,
      "z": -21,
      "name": "Rock_Volcanic_Cobble"
    },
    {
      "x": -51,
      "y": 37,
      "z": -21,
      "name": "Rock_Volcanic_Cobble"
    },
    {
      "x": -51,
      "y": 38,
      "z": -21,
      "name": "Rock_Volcanic_Cobble"
    },
    {
      "x": -51,
      "y": 39,
      "z": -21,
      "name": "Rock_Volcanic_Cobble"
    },
    {
      "x": -51,
      "y": 40,
      "z": -21,
      "name": "Rock_Volcanic_Brick"
    },
    {
      "x": -51,
      "y": 41,
      "z": -21,
      "name": "Rock_Volcanic_Brick"
    },
    {
      "x": -51,
      "y": 42,
      "z": -21,
      "name": "Rock_Volcanic_Brick"
    },
    {
      "x": -51,
      "y": 43,
      "z": -21,
      "name": "Rock_Volcanic_Brick"
    },
    {
      "x": -51,
      "y": 32,
      "z": -20,
      "name": "Rock_Volcanic"
    },
    {
      "x": -51,
      "y": 33,
      "z": -20,
      "name": "Rock_Volcanic_Cobble"
    },
    {
      "x": -51,
      "y": 34,
      "z": -20,
      "name": "Rock_Volcanic_Cobble"
    },
    {
      "x": -51,
      "y": 35,
      "z": -20,
      "name": "Rock_Volcanic_Cobble"
    },
    {
      "x": -51,
      "y": 36,
      "z": -20,
      "name": "Rock_Volcanic_Cobble"
    },
    {
      "x": -51,
      "y": 37,
      "z": -20,
      "name": "Rock_Volcanic_Cobble"
    },
    {
      "x": -51,
      "y": 38,
      "z": -20,
      "name": "Rock_Volcanic_Cobble"
    },
    {
      "x": -51,
      "y": 39,
      "z": -20,
      "name": "Rock_Volcanic_Cobble"
    },
    {
      "x": -51,
      "y": 40,
      "z": -20,
      "name": "Rock_Volcanic_Brick"
    },
    {
      "x": -51,
      "y": 41,
      "z": -20,
      "name": "Rock_Volcanic_Brick"
    },
    {
      "x": -51,
      "y": 42,
      "z": -20,
      "name": "Rock_Volcanic_Brick"
    },
    {
      "x": -51,
      "y": 43,
      "z": -20,
      "name": "Rock_Volcanic_Brick"
    },
    {
      "x": -51,
      "y": 32,
      "z": -19,
      "name": "Rock_Volcanic"
    },
    {
      "x": -51,
      "y": 33,
      "z": -19,
      "name": "Rock_Volcanic_Cobble"
    },
    {
      "x": -51,
      "y": 34,
      "z": -19,
      "name": "Rock_Volcanic_Cobble"
    },
    {
      "x": -51,
      "y": 35,
      "z": -19,
      "name": "Rock_Volcanic_Cobble"
    },
    {
      "x": -51,
      "y": 36,
      "z": -19,
      "name": "Rock_Volcanic_Cobble"
    },
    {
      "x": -51,
      "y": 37,
      "z": -19,
      "name": "Rock_Volcanic_Cobble"
    },
    {
      "x": -51,
      "y": 38,
      "z": -19,
      "name": "Rock_Volcanic_Cobble"
    },
    {
      "x": -51,
      "y": 39,
      "z": -19,
      "name": "Rock_Volcanic_Cobble"
    },
    {
      "x": -51,
      "y": 40,
      "z": -19,
      "name": "Rock_Volcanic_Cobble"
    },
    {
      "x": -51,
      "y": 41,
      "z": -19,
      "name": "Rock_Volcanic"
    },
    {
      "x": -51,
      "y": 42,
      "z": -19,
      "name": "Rock_Volcanic"
    },
    {
      "x": -51,
      "y": 43,
      "z": -19,
      "name": "Rock_Volcanic"
    },
    {
      "x": -51,
      "y": 44,
      "z": -19,
      "name": "Rock_Volcanic_Brick"
    },
    {
      "x": -51,
      "y": 33,
      "z": -18,
      "name": "Rock_Volcanic"
    },
    {
      "x": -51,
      "y": 34,
      "z": -18,
      "name": "Rock_Volcanic_Cobble"
    },
    {
      "x": -51,
      "y": 35,
      "z": -18,
      "name": "Rock_Volcanic_Cobble"
    },
    {
      "x": -51,
      "y": 36,
      "z": -18,
      "name": "Rock_Volcanic_Cobble"
    },
    {
      "x": -51,
      "y": 37,
      "z": -18,
      "name": "Rock_Volcanic_Cobble"
    },
    {
      "x": -51,
      "y": 38,
      "z": -18,
      "name": "Rock_Volcanic_Cobble"
    },
    {
      "x": -51,
      "y": 39,
      "z": -18,
      "name": "Rock_Volcanic_Cobble"
    },
    {
      "x": -51,
      "y": 40,
      "z": -18,
      "name": "Rock_Volcanic_Cobble"
    },
    {
      "x": -51,
      "y": 41,
      "z": -18,
      "name": "Rock_Volcanic_Cobble"
    },
    {
      "x": -51,
      "y": 42,
      "z": -18,
      "name": "Rock_Volcanic"
    },
    {
      "x": -51,
      "y": 43,
      "z": -18,
      "name": "Rock_Volcanic"
    },
    {
      "x": -51,
      "y": 44,
      "z": -18,
      "name": "Rock_Volcanic_Brick"
    },
    {
      "x": -51,
      "y": 45,
      "z": -18,
      "name": "Rock_Volcanic_Brick"
    },
    {
      "x": -51,
      "y": 34,
      "z": -17,
      "name": "Rock_Volcanic"
    },
    {
      "x": -51,
      "y": 35,
      "z": -17,
      "name": "Rock_Volcanic_Cobble"
    },
    {
      "x": -51,
      "y": 36,
      "z": -17,
      "name": "Rock_Volcanic_Cobble"
    },
    {
      "x": -51,
      "y": 37,
      "z": -17,
      "name": "Rock_Volcanic_Cobble"
    },
    {
      "x": -51,
      "y": 38,
      "z": -17,
      "name": "Rock_Volcanic_Cobble"
    },
    {
      "x": -51,
      "y": 39,
      "z": -17,
      "name": "Rock_Volcanic_Cobble"
    },
    {
      "x": -51,
      "y": 40,
      "z": -17,
      "name": "Rock_Volcanic_Cobble"
    },
    {
      "x": -51,
      "y": 41,
      "z": -17,
      "name": "Rock_Volcanic_Cobble"
    },
    {
      "x": -51,
      "y": 42,
      "z": -17,
      "name": "Rock_Volcanic_Cobble"
    },
    {
      "x": -51,
      "y": 43,
      "z": -17,
      "name": "Rock_Volcanic"
    },
    {
      "x": -51,
      "y": 44,
      "z": -17,
      "name": "Rock_Volcanic"
    },
    {
      "x": -51,
      "y": 45,
      "z": -17,
      "name": "Rock_Volcanic_Brick"
    },
    {
      "x": -51,
      "y": 36,
      "z": -16,
      "name": "Rock_Volcanic_Cobble"
    },
    {
      "x": -51,
      "y": 37,
      "z": -16,
      "name": "Rock_Volcanic_Cobble"
    },
    {
      "x": -51,
      "y": 38,
      "z": -16,
      "name": "Rock_Volcanic_Cobble"
    },
    {
      "x": -51,
      "y": 39,
      "z": -16,
      "name": "Rock_Volcanic_Cobble"
    },
    {
      "x": -51,
      "y": 40,
      "z": -16,
      "name": "Rock_Volcanic_Cobble"
    },
    {
      "x": -51,
      "y": 41,
      "z": -16,
      "name": "Rock_Volcanic_Brick"
    },
    {
      "x": -51,
      "y": 42,
      "z": -16,
      "name": "Rock_Volcanic_Brick"
    },
    {
      "x": -51,
      "y": 43,
      "z": -16,
      "name": "Rock_Volcanic_Brick"
    },
    {
      "x": -51,
      "y": 44,
      "z": -16,
      "name": "Rock_Volcanic_Brick"
    },
    {
      "x": -51,
      "y": 45,
      "z": -16,
      "name": "Rock_Volcanic_Brick"
    },
    {
      "x": -51,
      "y": 46,
      "z": -16,
      "name": "Rock_Volcanic_Brick"
    },
    {
      "x": -51,
      "y": 42,
      "z": -15,
      "name": "Rock_Volcanic_Brick"
    },
    {
      "x": -51,
      "y": 43,
      "z": -15,
      "name": "Rock_Volcanic_Brick"
    },
    {
      "x": -51,
      "y": 44,
      "z": -15,
      "name": "Rock_Volcanic_Brick"
    },
    {
      "x": -51,
      "y": 45,
      "z": -15,
      "name": "Rock_Volcanic_Brick"
    },
    {
      "x": -51,
      "y": 46,
      "z": -15,
      "name": "Rock_Volcanic_Brick"
    },
    {
      "x": -51,
      "y": 47,
      "z": -15,
      "name": "Rock_Volcanic_Brick"
    },
    {
      "x": -50,
      "y": 34,
      "z": -36,
      "name": "Rock_Volcanic"
    },
    {
      "x": -50,
      "y": 35,
      "z": -36,
      "name": "Rock_Volcanic"
    },
    {
      "x": -50,
      "y": 36,
      "z": -36,
      "name": "Rock_Volcanic_Cobble"
    },
    {
      "x": -50,
      "y": 37,
      "z": -36,
      "name": "Rock_Volcanic_Cobble"
    },
    {
      "x": -50,
      "y": 38,
      "z": -36,
      "name": "Rock_Volcanic_Cobble"
    },
    {
      "x": -50,
      "y": 39,
      "z": -36,
      "name": "Rock_Volcanic_Cobble"
    },
    {
      "x": -50,
      "y": 40,
      "z": -36,
      "name": "Rock_Volcanic_Cobble"
    },
    {
      "x": -50,
      "y": 41,
      "z": -36,
      "name": "Rock_Volcanic_Brick"
    },
    {
      "x": -50,
      "y": 42,
      "z": -36,
      "name": "Rock_Volcanic_Brick"
    },
    {
      "x": -50,
      "y": 43,
      "z": -36,
      "name": "Rock_Volcanic_Brick"
    },
    {
      "x": -50,
      "y": 44,
      "z": -36,
      "name": "Rock_Volcanic_Brick"
    },
    {
      "x": -50,
      "y": 45,
      "z": -36,
      "name": "Rock_Volcanic_Brick"
    },
    {
      "x": -50,
      "y": 46,
      "z": -36,
      "name": "Rock_Volcanic_Brick"
    },
    {
      "x": -50,
      "y": 21,
      "z": -35,
      "name": "Rock_Volcanic"
    },
    {
      "x": -50,
      "y": 22,
      "z": -35,
      "name": "Rock_Volcanic"
    },
    {
      "x": -50,
      "y": 23,
      "z": -35,
      "name": "Rock_Volcanic"
    },
    {
      "x": -50,
      "y": 24,
      "z": -35,
      "name": "Rock_Volcanic"
    },
    {
      "x": -50,
      "y": 25,
      "z": -35,
      "name": "Rock_Volcanic"
    },
    {
      "x": -50,
      "y": 26,
      "z": -35,
      "name": "Rock_Volcanic"
    },
    {
      "x": -50,
      "y": 32,
      "z": -35,
      "name": "Rock_Volcanic"
    },
    {
      "x": -50,
      "y": 33,
      "z": -35,
      "name": "Rock_Volcanic"
    },
    {
      "x": -50,
      "y": 34,
      "z": -35,
      "name": "Rock_Volcanic"
    },
    {
      "x": -50,
      "y": 35,
      "z": -35,
      "name": "Rock_Volcanic"
    },
    {
      "x": -50,
      "y": 36,
      "z": -35,
      "name": "Rock_Volcanic_Cobble"
    },
    {
      "x": -50,
      "y": 37,
      "z": -35,
      "name": "Rock_Volcanic_Cobble"
    },
    {
      "x": -50,
      "y": 38,
      "z": -35,
      "name": "Rock_Volcanic_Cobble"
    },
    {
      "x": -50,
      "y": 39,
      "z": -35,
      "name": "Rock_Volcanic_Cobble"
    },
    {
      "x": -50,
      "y": 40,
      "z": -35,
      "name": "Rock_Volcanic_Cobble"
    },
    {
      "x": -50,
      "y": 41,
      "z": -35,
      "name": "Rock_Volcanic_Cobble"
    },
    {
      "x": -50,
      "y": 42,
      "z": -35,
      "name": "Rock_Volcanic_Cobble"
    },
    {
      "x": -50,
      "y": 43,
      "z": -35,
      "name": "Rock_Volcanic_Cobble"
    },
    {
      "x": -50,
      "y": 44,
      "z": -35,
      "name": "Rock_Volcanic_Brick"
    },
    {
      "x": -50,
      "y": 45,
      "z": -35,
      "name": "Rock_Volcanic_Brick"
    },
    {
      "x": -50,
      "y": 21,
      "z": -34,
      "name": "Rock_Volcanic"
    },
    {
      "x": -50,
      "y": 22,
      "z": -34,
      "name": "Rock_Volcanic"
    },
    {
      "x": -50,
      "y": 23,
      "z": -34,
      "name": "Rock_Volcanic"
    },
    {
      "x": -50,
      "y": 24,
      "z": -34,
      "name": "Rock_Volcanic"
    },
    {
      "x": -50,
      "y": 25,
      "z": -34,
      "name": "Rock_Volcanic"
    },
    {
      "x": -50,
      "y": 26,
      "z": -34,
      "name": "Rock_Volcanic"
    },
    {
      "x": -50,
      "y": 27,
      "z": -34,
      "name": "Rock_Volcanic"
    },
    {
      "x": -50,
      "y": 28,
      "z": -34,
      "name": "Rock_Volcanic"
    },
    {
      "x": -50,
      "y": 29,
      "z": -34,
      "name": "Rock_Volcanic"
    },
    {
      "x": -50,
      "y": 30,
      "z": -34,
      "name": "Rock_Volcanic"
    },
    {
      "x": -50,
      "y": 31,
      "z": -34,
      "name": "Rock_Volcanic"
    },
    {
      "x": -50,
      "y": 32,
      "z": -34,
      "name": "Rock_Volcanic"
    },
    {
      "x": -50,
      "y": 33,
      "z": -34,
      "name": "Rock_Volcanic"
    },
    {
      "x": -50,
      "y": 34,
      "z": -34,
      "name": "Rock_Volcanic"
    },
    {
      "x": -50,
      "y": 35,
      "z": -34,
      "name": "Rock_Volcanic"
    },
    {
      "x": -50,
      "y": 36,
      "z": -34,
      "name": "Rock_Volcanic_Cobble"
    },
    {
      "x": -50,
      "y": 37,
      "z": -34,
      "name": "Rock_Volcanic_Cobble"
    },
    {
      "x": -50,
      "y": 38,
      "z": -34,
      "name": "Rock_Volcanic_Cobble"
    },
    {
      "x": -50,
      "y": 39,
      "z": -34,
      "name": "Rock_Volcanic_Cobble"
    },
    {
      "x": -50,
      "y": 40,
      "z": -34,
      "name": "Rock_Volcanic_Cobble"
    },
    {
      "x": -50,
      "y": 41,
      "z": -34,
      "name": "Rock_Volcanic_Cobble"
    },
    {
      "x": -50,
      "y": 42,
      "z": -34,
      "name": "Rock_Volcanic_Cobble"
    },
    {
      "x": -50,
      "y": 43,
      "z": -34,
      "name": "Rock_Volcanic_Brick"
    },
    {
      "x": -50,
      "y": 44,
      "z": -34,
      "name": "Rock_Volcanic_Brick"
    },
    {
      "x": -50,
      "y": 21,
      "z": -33,
      "name": "Rock_Volcanic"
    },
    {
      "x": -50,
      "y": 22,
      "z": -33,
      "name": "Rock_Volcanic"
    },
    {
      "x": -50,
      "y": 23,
      "z": -33,
      "name": "Rock_Volcanic"
    },
    {
      "x": -50,
      "y": 24,
      "z": -33,
      "name": "Rock_Volcanic"
    },
    {
      "x": -50,
      "y": 25,
      "z": -33,
      "name": "Rock_Volcanic"
    },
    {
      "x": -50,
      "y": 26,
      "z": -33,
      "name": "Rock_Volcanic"
    },
    {
      "x": -50,
      "y": 27,
      "z": -33,
      "name": "Rock_Volcanic"
    },
    {
      "x": -50,
      "y": 28,
      "z": -33,
      "name": "Rock_Volcanic"
    },
    {
      "x": -50,
      "y": 29,
      "z": -33,
      "name": "Rock_Volcanic"
    },
    {
      "x": -50,
      "y": 30,
      "z": -33,
      "name": "Rock_Volcanic"
    },
    {
      "x": -50,
      "y": 31,
      "z": -33,
      "name": "Rock_Volcanic"
    },
    {
      "x": -50,
      "y": 32,
      "z": -33,
      "name": "Rock_Volcanic"
    },
    {
      "x": -50,
      "y": 33,
      "z": -33,
      "name": "Rock_Volcanic"
    },
    {
      "x": -50,
      "y": 34,
      "z": -33,
      "name": "Rock_Volcanic"
    },
    {
      "x": -50,
      "y": 35,
      "z": -33,
      "name": "Rock_Volcanic"
    },
    {
      "x": -50,
      "y": 36,
      "z": -33,
      "name": "Rock_Volcanic"
    },
    {
      "x": -50,
      "y": 37,
      "z": -33,
      "name": "Rock_Volcanic_Cobble"
    },
    {
      "x": -50,
      "y": 38,
      "z": -33,
      "name": "Rock_Volcanic_Cobble"
    },
    {
      "x": -50,
      "y": 39,
      "z": -33,
      "name": "Rock_Volcanic_Cobble"
    },
    {
      "x": -50,
      "y": 40,
      "z": -33,
      "name": "Rock_Volcanic_Cobble"
    },
    {
      "x": -50,
      "y": 41,
      "z": -33,
      "name": "Rock_Volcanic_Cobble"
    },
    {
      "x": -50,
      "y": 42,
      "z": -33,
      "name": "Rock_Volcanic_Cobble"
    },
    {
      "x": -50,
      "y": 43,
      "z": -33,
      "name": "Rock_Volcanic_Brick"
    },
    {
      "x": -50,
      "y": 21,
      "z": -32,
      "name": "Rock_Volcanic"
    },
    {
      "x": -50,
      "y": 22,
      "z": -32,
      "name": "Rock_Volcanic"
    },
    {
      "x": -50,
      "y": 23,
      "z": -32,
      "name": "Rock_Volcanic"
    },
    {
      "x": -50,
      "y": 24,
      "z": -32,
      "name": "Rock_Volcanic"
    },
    {
      "x": -50,
      "y": 25,
      "z": -32,
      "name": "Rock_Volcanic"
    },
    {
      "x": -50,
      "y": 26,
      "z": -32,
      "name": "Rock_Volcanic"
    },
    {
      "x": -50,
      "y": 27,
      "z": -32,
      "name": "Rock_Volcanic"
    },
    {
      "x": -50,
      "y": 28,
      "z": -32,
      "name": "Rock_Volcanic"
    },
    {
      "x": -50,
      "y": 29,
      "z": -32,
      "name": "Rock_Volcanic"
    },
    {
      "x": -50,
      "y": 30,
      "z": -32,
      "name": "Rock_Volcanic"
    },
    {
      "x": -50,
      "y": 31,
      "z": -32,
      "name": "Rock_Volcanic"
    },
    {
      "x": -50,
      "y": 32,
      "z": -32,
      "name": "Rock_Volcanic"
    },
    {
      "x": -50,
      "y": 33,
      "z": -32,
      "name": "Rock_Volcanic"
    },
    {
      "x": -50,
      "y": 34,
      "z": -32,
      "name": "Rock_Volcanic"
    },
    {
      "x": -50,
      "y": 35,
      "z": -32,
      "name": "Rock_Volcanic"
    },
    {
      "x": -50,
      "y": 36,
      "z": -32,
      "name": "Rock_Volcanic_Cobble"
    },
    {
      "x": -50,
      "y": 37,
      "z": -32,
      "name": "Rock_Volcanic_Cobble"
    },
    {
      "x": -50,
      "y": 38,
      "z": -32,
      "name": "Rock_Volcanic_Cobble"
    },
    {
      "x": -50,
      "y": 39,
      "z": -32,
      "name": "Rock_Volcanic_Cobble"
    },
    {
      "x": -50,
      "y": 40,
      "z": -32,
      "name": "Rock_Volcanic_Cobble"
    },
    {
      "x": -50,
      "y": 41,
      "z": -32,
      "name": "Rock_Volcanic_Cobble"
    },
    {
      "x": -50,
      "y": 42,
      "z": -32,
      "name": "Rock_Volcanic_Brick"
    },
    {
      "x": -50,
      "y": 43,
      "z": -32,
      "name": "Rock_Volcanic_Brick"
    },
    {
      "x": -50,
      "y": 22,
      "z": -31,
      "name": "Rock_Volcanic"
    },
    {
      "x": -50,
      "y": 23,
      "z": -31,
      "name": "Rock_Volcanic"
    },
    {
      "x": -50,
      "y": 24,
      "z": -31,
      "name": "Rock_Volcanic"
    },
    {
      "x": -50,
      "y": 25,
      "z": -31,
      "name": "Rock_Volcanic"
    },
    {
      "x": -50,
      "y": 26,
      "z": -31,
      "name": "Rock_Volcanic"
    },
    {
      "x": -50,
      "y": 27,
      "z": -31,
      "name": "Rock_Volcanic"
    },
    {
      "x": -50,
      "y": 28,
      "z": -31,
      "name": "Rock_Volcanic"
    },
    {
      "x": -50,
      "y": 29,
      "z": -31,
      "name": "Rock_Volcanic"
    },
    {
      "x": -50,
      "y": 30,
      "z": -31,
      "name": "Rock_Volcanic"
    },
    {
      "x": -50,
      "y": 31,
      "z": -31,
      "name": "Rock_Volcanic"
    },
    {
      "x": -50,
      "y": 32,
      "z": -31,
      "name": "Rock_Volcanic"
    },
    {
      "x": -50,
      "y": 33,
      "z": -31,
      "name": "Rock_Volcanic"
    },
    {
      "x": -50,
      "y": 34,
      "z": -31,
      "name": "Rock_Volcanic"
    },
    {
      "x": -50,
      "y": 35,
      "z": -31,
      "name": "Rock_Volcanic_Cobble"
    },
    {
      "x": -50,
      "y": 36,
      "z": -31,
      "name": "Rock_Volcanic_Cobble"
    },
    {
      "x": -50,
      "y": 37,
      "z": -31,
      "name": "Rock_Volcanic_Cobble"
    },
    {
      "x": -50,
      "y": 38,
      "z": -31,
      "name": "Rock_Volcanic_Cobble"
    },
    {
      "x": -50,
      "y": 39,
      "z": -31,
      "name": "Rock_Volcanic_Brick"
    },
    {
      "x": -50,
      "y": 40,
      "z": -31,
      "name": "Rock_Volcanic_Brick"
    },
    {
      "x": -50,
      "y": 41,
      "z": -31,
      "name": "Rock_Volcanic_Cobble"
    },
    {
      "x": -50,
      "y": 42,
      "z": -31,
      "name": "Rock_Volcanic_Brick"
    },
    {
      "x": -50,
      "y": 25,
      "z": -30,
      "name": "Rock_Volcanic"
    },
    {
      "x": -50,
      "y": 26,
      "z": -30,
      "name": "Rock_Volcanic"
    },
    {
      "x": -50,
      "y": 27,
      "z": -30,
      "name": "Rock_Volcanic"
    },
    {
      "x": -50,
      "y": 28,
      "z": -30,
      "name": "Rock_Volcanic"
    },
    {
      "x": -50,
      "y": 29,
      "z": -30,
      "name": "Rock_Volcanic"
    },
    {
      "x": -50,
      "y": 30,
      "z": -30,
      "name": "Rock_Volcanic"
    },
    {
      "x": -50,
      "y": 31,
      "z": -30,
      "name": "Rock_Volcanic"
    },
    {
      "x": -50,
      "y": 32,
      "z": -30,
      "name": "Rock_Volcanic"
    },
    {
      "x": -50,
      "y": 33,
      "z": -30,
      "name": "Rock_Volcanic"
    },
    {
      "x": -50,
      "y": 34,
      "z": -30,
      "name": "Rock_Volcanic_Cobble"
    },
    {
      "x": -50,
      "y": 35,
      "z": -30,
      "name": "Rock_Volcanic_Cobble"
    },
    {
      "x": -50,
      "y": 36,
      "z": -30,
      "name": "Rock_Volcanic_Cobble"
    },
    {
      "x": -50,
      "y": 37,
      "z": -30,
      "name": "Rock_Volcanic_Brick"
    },
    {
      "x": -50,
      "y": 38,
      "z": -30,
      "name": "Rock_Volcanic_Brick"
    },
    {
      "x": -50,
      "y": 39,
      "z": -30,
      "name": "Rock_Volcanic_Brick"
    },
    {
      "x": -50,
      "y": 40,
      "z": -30,
      "name": "Rock_Volcanic_Brick"
    },
    {
      "x": -50,
      "y": 41,
      "z": -30,
      "name": "Rock_Volcanic_Brick"
    },
    {
      "x": -50,
      "y": 26,
      "z": -29,
      "name": "Rock_Volcanic"
    },
    {
      "x": -50,
      "y": 27,
      "z": -29,
      "name": "Rock_Volcanic"
    },
    {
      "x": -50,
      "y": 28,
      "z": -29,
      "name": "Rock_Volcanic"
    },
    {
      "x": -50,
      "y": 29,
      "z": -29,
      "name": "Rock_Volcanic"
    },
    {
      "x": -50,
      "y": 30,
      "z": -29,
      "name": "Rock_Volcanic"
    },
    {
      "x": -50,
      "y": 31,
      "z": -29,
      "name": "Rock_Volcanic"
    },
    {
      "x": -50,
      "y": 32,
      "z": -29,
      "name": "Rock_Volcanic"
    },
    {
      "x": -50,
      "y": 40,
      "z": -29,
      "name": "Rock_Volcanic_Brick"
    },
    {
      "x": -50,
      "y": 27,
      "z": -28,
      "name": "Rock_Volcanic"
    },
    {
      "x": -50,
      "y": 28,
      "z": -28,
      "name": "Rock_Volcanic"
    },
    {
      "x": -50,
      "y": 29,
      "z": -28,
      "name": "Rock_Volcanic"
    },
    {
      "x": -50,
      "y": 29,
      "z": -23,
      "name": "Rock_Volcanic"
    },
    {
      "x": -50,
      "y": 40,
      "z": -23,
      "name": "Rock_Volcanic_Brick"
    },
    {
      "x": -50,
      "y": 29,
      "z": -22,
      "name": "Rock_Volcanic"
    },
    {
      "x": -50,
      "y": 30,
      "z": -22,
      "name": "Rock_Volcanic"
    },
    {
      "x": -50,
      "y": 31,
      "z": -22,
      "name": "Rock_Volcanic"
    },
    {
      "x": -50,
      "y": 32,
      "z": -22,
      "name": "Rock_Volcanic"
    },
    {
      "x": -50,
      "y": 33,
      "z": -22,
      "name": "Rock_Volcanic"
    },
    {
      "x": -50,
      "y": 35,
      "z": -22,
      "name": "Rock_Volcanic_Cobble"
    },
    {
      "x": -50,
      "y": 36,
      "z": -22,
      "name": "Rock_Volcanic_Brick"
    },
    {
      "x": -50,
      "y": 37,
      "z": -22,
      "name": "Rock_Volcanic_Brick"
    },
    {
      "x": -50,
      "y": 38,
      "z": -22,
      "name": "Rock_Volcanic_Brick"
    },
    {
      "x": -50,
      "y": 39,
      "z": -22,
      "name": "Rock_Volcanic_Brick"
    },
    {
      "x": -50,
      "y": 40,
      "z": -22,
      "name": "Rock_Volcanic_Brick"
    },
    {
      "x": -50,
      "y": 41,
      "z": -22,
      "name": "Rock_Volcanic_Brick"
    },
    {
      "x": -50,
      "y": 29,
      "z": -21,
      "name": "Rock_Volcanic"
    },
    {
      "x": -50,
      "y": 30,
      "z": -21,
      "name": "Rock_Volcanic"
    },
    {
      "x": -50,
      "y": 31,
      "z": -21,
      "name": "Rock_Volcanic"
    },
    {
      "x": -50,
      "y": 32,
      "z": -21,
      "name": "Rock_Volcanic"
    },
    {
      "x": -50,
      "y": 33,
      "z": -21,
      "name": "Rock_Volcanic"
    },
    {
      "x": -50,
      "y": 34,
      "z": -21,
      "name": "Rock_Volcanic_Cobble"
    },
    {
      "x": -50,
      "y": 35,
      "z": -21,
      "name": "Rock_Volcanic_Cobble"
    },
    {
      "x": -50,
      "y": 36,
      "z": -21,
      "name": "Rock_Volcanic_Cobble"
    },
    {
      "x": -50,
      "y": 37,
      "z": -21,
      "name": "Rock_Volcanic_Brick"
    },
    {
      "x": -50,
      "y": 38,
      "z": -21,
      "name": "Rock_Volcanic_Cobble"
    },
    {
      "x": -50,
      "y": 39,
      "z": -21,
      "name": "Rock_Volcanic_Brick"
    },
    {
      "x": -50,
      "y": 40,
      "z": -21,
      "name": "Rock_Volcanic_Brick"
    },
    {
      "x": -50,
      "y": 41,
      "z": -21,
      "name": "Rock_Volcanic"
    },
    {
      "x": -50,
      "y": 42,
      "z": -21,
      "name": "Rock_Volcanic_Brick"
    },
    {
      "x": -50,
      "y": 29,
      "z": -20,
      "name": "Rock_Volcanic"
    },
    {
      "x": -50,
      "y": 30,
      "z": -20,
      "name": "Rock_Volcanic"
    },
    {
      "x": -50,
      "y": 31,
      "z": -20,
      "name": "Rock_Volcanic"
    },
    {
      "x": -50,
      "y": 32,
      "z": -20,
      "name": "Rock_Volcanic"
    },
    {
      "x": -50,
      "y": 33,
      "z": -20,
      "name": "Rock_Volcanic"
    },
    {
      "x": -50,
      "y": 34,
      "z": -20,
      "name": "Rock_Volcanic_Cobble"
    },
    {
      "x": -50,
      "y": 35,
      "z": -20,
      "name": "Rock_Volcanic_Cobble"
    },
    {
      "x": -50,
      "y": 36,
      "z": -20,
      "name": "Rock_Volcanic_Cobble"
    },
    {
      "x": -50,
      "y": 37,
      "z": -20,
      "name": "Rock_Volcanic_Cobble"
    },
    {
      "x": -50,
      "y": 38,
      "z": -20,
      "name": "Rock_Volcanic_Cobble"
    },
    {
      "x": -50,
      "y": 39,
      "z": -20,
      "name": "Rock_Volcanic_Cobble"
    },
    {
      "x": -50,
      "y": 40,
      "z": -20,
      "name": "Rock_Volcanic"
    },
    {
      "x": -50,
      "y": 41,
      "z": -20,
      "name": "Rock_Volcanic"
    },
    {
      "x": -50,
      "y": 42,
      "z": -20,
      "name": "Rock_Volcanic_Brick"
    },
    {
      "x": -50,
      "y": 43,
      "z": -20,
      "name": "Rock_Volcanic_Brick"
    },
    {
      "x": -50,
      "y": 30,
      "z": -19,
      "name": "Rock_Volcanic"
    },
    {
      "x": -50,
      "y": 31,
      "z": -19,
      "name": "Rock_Volcanic"
    },
    {
      "x": -50,
      "y": 32,
      "z": -19,
      "name": "Rock_Volcanic"
    },
    {
      "x": -50,
      "y": 33,
      "z": -19,
      "name": "Rock_Volcanic"
    },
    {
      "x": -50,
      "y": 34,
      "z": -19,
      "name": "Rock_Volcanic_Cobble"
    },
    {
      "x": -50,
      "y": 35,
      "z": -19,
      "name": "Rock_Volcanic_Cobble"
    },
    {
      "x": -50,
      "y": 36,
      "z": -19,
      "name": "Rock_Volcanic_Cobble"
    },
    {
      "x": -50,
      "y": 37,
      "z": -19,
      "name": "Rock_Volcanic_Cobble"
    },
    {
      "x": -50,
      "y": 38,
      "z": -19,
      "name": "Rock_Volcanic_Cobble"
    },
    {
      "x": -50,
      "y": 39,
      "z": -19,
      "name": "Rock_Volcanic_Cobble"
    },
    {
      "x": -50,
      "y": 40,
      "z": -19,
      "name": "Rock_Volcanic_Cobble"
    },
    {
      "x": -50,
      "y": 41,
      "z": -19,
      "name": "Rock_Volcanic"
    },
    {
      "x": -50,
      "y": 42,
      "z": -19,
      "name": "Rock_Volcanic"
    },
    {
      "x": -50,
      "y": 43,
      "z": -19,
      "name": "Rock_Volcanic_Brick"
    },
    {
      "x": -50,
      "y": 30,
      "z": -18,
      "name": "Rock_Volcanic"
    },
    {
      "x": -50,
      "y": 31,
      "z": -18,
      "name": "Rock_Volcanic"
    },
    {
      "x": -50,
      "y": 32,
      "z": -18,
      "name": "Rock_Volcanic"
    },
    {
      "x": -50,
      "y": 33,
      "z": -18,
      "name": "Rock_Volcanic"
    },
    {
      "x": -50,
      "y": 34,
      "z": -18,
      "name": "Rock_Volcanic"
    },
    {
      "x": -50,
      "y": 35,
      "z": -18,
      "name": "Rock_Volcanic_Cobble"
    },
    {
      "x": -50,
      "y": 36,
      "z": -18,
      "name": "Rock_Volcanic_Cobble"
    },
    {
      "x": -50,
      "y": 37,
      "z": -18,
      "name": "Rock_Volcanic_Cobble"
    },
    {
      "x": -50,
      "y": 38,
      "z": -18,
      "name": "Rock_Volcanic_Cobble"
    },
    {
      "x": -50,
      "y": 39,
      "z": -18,
      "name": "Rock_Volcanic_Cobble"
    },
    {
      "x": -50,
      "y": 40,
      "z": -18,
      "name": "Rock_Volcanic_Cobble"
    },
    {
      "x": -50,
      "y": 41,
      "z": -18,
      "name": "Rock_Volcanic_Cobble"
    },
    {
      "x": -50,
      "y": 42,
      "z": -18,
      "name": "Rock_Volcanic"
    },
    {
      "x": -50,
      "y": 43,
      "z": -18,
      "name": "Rock_Volcanic_Brick"
    },
    {
      "x": -50,
      "y": 44,
      "z": -18,
      "name": "Rock_Volcanic_Brick"
    },
    {
      "x": -50,
      "y": 33,
      "z": -17,
      "name": "Rock_Volcanic"
    },
    {
      "x": -50,
      "y": 34,
      "z": -17,
      "name": "Rock_Volcanic"
    },
    {
      "x": -50,
      "y": 35,
      "z": -17,
      "name": "Rock_Volcanic_Cobble"
    },
    {
      "x": -50,
      "y": 36,
      "z": -17,
      "name": "Rock_Volcanic_Cobble"
    },
    {
      "x": -50,
      "y": 37,
      "z": -17,
      "name": "Rock_Volcanic_Cobble"
    },
    {
      "x": -50,
      "y": 38,
      "z": -17,
      "name": "Rock_Volcanic_Cobble"
    },
    {
      "x": -50,
      "y": 39,
      "z": -17,
      "name": "Rock_Volcanic_Cobble"
    },
    {
      "x": -50,
      "y": 40,
      "z": -17,
      "name": "Rock_Volcanic_Cobble"
    },
    {
      "x": -50,
      "y": 41,
      "z": -17,
      "name": "Rock_Volcanic_Cobble"
    },
    {
      "x": -50,
      "y": 42,
      "z": -17,
      "name": "Rock_Volcanic_Cobble"
    },
    {
      "x": -50,
      "y": 43,
      "z": -17,
      "name": "Rock_Volcanic"
    },
    {
      "x": -50,
      "y": 44,
      "z": -17,
      "name": "Rock_Volcanic_Brick"
    },
    {
      "x": -50,
      "y": 45,
      "z": -17,
      "name": "Rock_Volcanic_Brick"
    },
    {
      "x": -50,
      "y": 35,
      "z": -16,
      "name": "Rock_Volcanic_Cobble"
    },
    {
      "x": -50,
      "y": 36,
      "z": -16,
      "name": "Rock_Volcanic_Cobble"
    },
    {
      "x": -50,
      "y": 37,
      "z": -16,
      "name": "Rock_Volcanic_Cobble"
    },
    {
      "x": -50,
      "y": 38,
      "z": -16,
      "name": "Rock_Volcanic_Cobble"
    },
    {
      "x": -50,
      "y": 39,
      "z": -16,
      "name": "Rock_Volcanic_Cobble"
    },
    {
      "x": -50,
      "y": 40,
      "z": -16,
      "name": "Rock_Volcanic_Cobble"
    },
    {
      "x": -50,
      "y": 41,
      "z": -16,
      "name": "Rock_Volcanic_Brick"
    },
    {
      "x": -50,
      "y": 42,
      "z": -16,
      "name": "Rock_Volcanic_Brick"
    },
    {
      "x": -50,
      "y": 43,
      "z": -16,
      "name": "Rock_Volcanic_Brick"
    },
    {
      "x": -50,
      "y": 44,
      "z": -16,
      "name": "Rock_Volcanic_Brick"
    },
    {
      "x": -50,
      "y": 45,
      "z": -16,
      "name": "Rock_Volcanic_Brick"
    },
    {
      "x": -50,
      "y": 46,
      "z": -16,
      "name": "Rock_Volcanic_Brick"
    },
    {
      "x": -49,
      "y": 33,
      "z": -36,
      "name": "Rock_Volcanic"
    },
    {
      "x": -49,
      "y": 34,
      "z": -36,
      "name": "Rock_Volcanic"
    },
    {
      "x": -49,
      "y": 35,
      "z": -36,
      "name": "Rock_Volcanic_Cobble"
    },
    {
      "x": -49,
      "y": 36,
      "z": -36,
      "name": "Rock_Volcanic_Cobble"
    },
    {
      "x": -49,
      "y": 39,
      "z": -36,
      "name": "Rock_Volcanic_Cobble"
    },
    {
      "x": -49,
      "y": 40,
      "z": -36,
      "name": "Rock_Volcanic_Cobble"
    },
    {
      "x": -49,
      "y": 41,
      "z": -36,
      "name": "Rock_Volcanic_Brick"
    },
    {
      "x": -49,
      "y": 42,
      "z": -36,
      "name": "Rock_Volcanic_Brick"
    },
    {
      "x": -49,
      "y": 43,
      "z": -36,
      "name": "Rock_Volcanic_Brick"
    },
    {
      "x": -49,
      "y": 44,
      "z": -36,
      "name": "Rock_Volcanic_Brick"
    },
    {
      "x": -49,
      "y": 21,
      "z": -35,
      "name": "Rock_Volcanic"
    },
    {
      "x": -49,
      "y": 22,
      "z": -35,
      "name": "Rock_Volcanic"
    },
    {
      "x": -49,
      "y": 23,
      "z": -35,
      "name": "Rock_Volcanic"
    },
    {
      "x": -49,
      "y": 24,
      "z": -35,
      "name": "Rock_Volcanic"
    },
    {
      "x": -49,
      "y": 25,
      "z": -35,
      "name": "Rock_Volcanic"
    },
    {
      "x": -49,
      "y": 26,
      "z": -35,
      "name": "Rock_Volcanic"
    },
    {
      "x": -49,
      "y": 29,
      "z": -35,
      "name": "Rock_Volcanic"
    },
    {
      "x": -49,
      "y": 30,
      "z": -35,
      "name": "Rock_Volcanic"
    },
    {
      "x": -49,
      "y": 31,
      "z": -35,
      "name": "Rock_Volcanic"
    },
    {
      "x": -49,
      "y": 32,
      "z": -35,
      "name": "Rock_Volcanic"
    },
    {
      "x": -49,
      "y": 33,
      "z": -35,
      "name": "Rock_Volcanic"
    },
    {
      "x": -49,
      "y": 34,
      "z": -35,
      "name": "Rock_Volcanic"
    },
    {
      "x": -49,
      "y": 35,
      "z": -35,
      "name": "Rock_Volcanic_Cobble"
    },
    {
      "x": -49,
      "y": 36,
      "z": -35,
      "name": "Rock_Volcanic_Cobble"
    },
    {
      "x": -49,
      "y": 37,
      "z": -35,
      "name": "Rock_Volcanic_Cobble"
    },
    {
      "x": -49,
      "y": 38,
      "z": -35,
      "name": "Rock_Volcanic_Cobble"
    },
    {
      "x": -49,
      "y": 39,
      "z": -35,
      "name": "Rock_Volcanic_Cobble"
    },
    {
      "x": -49,
      "y": 40,
      "z": -35,
      "name": "Rock_Volcanic_Brick"
    },
    {
      "x": -49,
      "y": 41,
      "z": -35,
      "name": "Rock_Volcanic_Cobble"
    },
    {
      "x": -49,
      "y": 42,
      "z": -35,
      "name": "Rock_Volcanic_Cobble"
    },
    {
      "x": -49,
      "y": 43,
      "z": -35,
      "name": "Rock_Volcanic_Brick"
    },
    {
      "x": -49,
      "y": 21,
      "z": -34,
      "name": "Rock_Volcanic"
    },
    {
      "x": -49,
      "y": 22,
      "z": -34,
      "name": "Rock_Volcanic"
    },
    {
      "x": -49,
      "y": 23,
      "z": -34,
      "name": "Rock_Volcanic"
    },
    {
      "x": -49,
      "y": 24,
      "z": -34,
      "name": "Rock_Volcanic"
    },
    {
      "x": -49,
      "y": 25,
      "z": -34,
      "name": "Rock_Volcanic"
    },
    {
      "x": -49,
      "y": 26,
      "z": -34,
      "name": "Rock_Volcanic"
    },
    {
      "x": -49,
      "y": 27,
      "z": -34,
      "name": "Rock_Volcanic"
    },
    {
      "x": -49,
      "y": 28,
      "z": -34,
      "name": "Rock_Volcanic"
    },
    {
      "x": -49,
      "y": 29,
      "z": -34,
      "name": "Rock_Volcanic"
    },
    {
      "x": -49,
      "y": 30,
      "z": -34,
      "name": "Rock_Volcanic"
    },
    {
      "x": -49,
      "y": 31,
      "z": -34,
      "name": "Rock_Volcanic"
    },
    {
      "x": -49,
      "y": 32,
      "z": -34,
      "name": "Rock_Volcanic"
    },
    {
      "x": -49,
      "y": 33,
      "z": -34,
      "name": "Rock_Volcanic"
    },
    {
      "x": -49,
      "y": 34,
      "z": -34,
      "name": "Rock_Volcanic"
    },
    {
      "x": -49,
      "y": 35,
      "z": -34,
      "name": "Rock_Volcanic_Cobble"
    },
    {
      "x": -49,
      "y": 36,
      "z": -34,
      "name": "Rock_Volcanic_Cobble"
    },
    {
      "x": -49,
      "y": 37,
      "z": -34,
      "name": "Rock_Volcanic_Cobble"
    },
    {
      "x": -49,
      "y": 38,
      "z": -34,
      "name": "Rock_Volcanic_Cobble"
    },
    {
      "x": -49,
      "y": 39,
      "z": -34,
      "name": "Rock_Volcanic_Cobble"
    },
    {
      "x": -49,
      "y": 40,
      "z": -34,
      "name": "Rock_Volcanic_Cobble"
    },
    {
      "x": -49,
      "y": 41,
      "z": -34,
      "name": "Rock_Volcanic_Cobble"
    },
    {
      "x": -49,
      "y": 42,
      "z": -34,
      "name": "Rock_Volcanic_Brick"
    },
    {
      "x": -49,
      "y": 43,
      "z": -34,
      "name": "Rock_Volcanic_Brick"
    },
    {
      "x": -49,
      "y": 21,
      "z": -33,
      "name": "Rock_Volcanic"
    },
    {
      "x": -49,
      "y": 22,
      "z": -33,
      "name": "Rock_Volcanic"
    },
    {
      "x": -49,
      "y": 23,
      "z": -33,
      "name": "Rock_Volcanic"
    },
    {
      "x": -49,
      "y": 24,
      "z": -33,
      "name": "Rock_Volcanic"
    },
    {
      "x": -49,
      "y": 25,
      "z": -33,
      "name": "Rock_Volcanic"
    },
    {
      "x": -49,
      "y": 26,
      "z": -33,
      "name": "Rock_Volcanic"
    },
    {
      "x": -49,
      "y": 27,
      "z": -33,
      "name": "Rock_Volcanic"
    },
    {
      "x": -49,
      "y": 28,
      "z": -33,
      "name": "Rock_Volcanic"
    },
    {
      "x": -49,
      "y": 29,
      "z": -33,
      "name": "Rock_Volcanic"
    },
    {
      "x": -49,
      "y": 30,
      "z": -33,
      "name": "Rock_Volcanic"
    },
    {
      "x": -49,
      "y": 31,
      "z": -33,
      "name": "Rock_Volcanic"
    },
    {
      "x": -49,
      "y": 32,
      "z": -33,
      "name": "Rock_Volcanic"
    },
    {
      "x": -49,
      "y": 33,
      "z": -33,
      "name": "Rock_Volcanic"
    },
    {
      "x": -49,
      "y": 34,
      "z": -33,
      "name": "Rock_Volcanic"
    },
    {
      "x": -49,
      "y": 35,
      "z": -33,
      "name": "Rock_Volcanic"
    },
    {
      "x": -49,
      "y": 36,
      "z": -33,
      "name": "Rock_Volcanic_Cobble"
    },
    {
      "x": -49,
      "y": 37,
      "z": -33,
      "name": "Rock_Volcanic_Cobble"
    },
    {
      "x": -49,
      "y": 38,
      "z": -33,
      "name": "Rock_Volcanic_Cobble"
    },
    {
      "x": -49,
      "y": 39,
      "z": -33,
      "name": "Rock_Volcanic_Cobble"
    },
    {
      "x": -49,
      "y": 40,
      "z": -33,
      "name": "Rock_Volcanic_Cobble"
    },
    {
      "x": -49,
      "y": 41,
      "z": -33,
      "name": "Rock_Volcanic_Cobble"
    },
    {
      "x": -49,
      "y": 42,
      "z": -33,
      "name": "Rock_Volcanic_Brick"
    },
    {
      "x": -49,
      "y": 43,
      "z": -33,
      "name": "Deco_Bone_Skulls"
    },
    {
      "x": -49,
      "y": 21,
      "z": -32,
      "name": "Rock_Volcanic"
    },
    {
      "x": -49,
      "y": 22,
      "z": -32,
      "name": "Rock_Volcanic"
    },
    {
      "x": -49,
      "y": 23,
      "z": -32,
      "name": "Rock_Volcanic"
    },
    {
      "x": -49,
      "y": 24,
      "z": -32,
      "name": "Rock_Volcanic"
    },
    {
      "x": -49,
      "y": 25,
      "z": -32,
      "name": "Rock_Volcanic"
    },
    {
      "x": -49,
      "y": 26,
      "z": -32,
      "name": "Rock_Volcanic"
    },
    {
      "x": -49,
      "y": 27,
      "z": -32,
      "name": "Rock_Volcanic"
    },
    {
      "x": -49,
      "y": 28,
      "z": -32,
      "name": "Rock_Volcanic"
    },
    {
      "x": -49,
      "y": 29,
      "z": -32,
      "name": "Rock_Volcanic"
    },
    {
      "x": -49,
      "y": 30,
      "z": -32,
      "name": "Rock_Volcanic"
    },
    {
      "x": -49,
      "y": 31,
      "z": -32,
      "name": "Rock_Volcanic"
    },
    {
      "x": -49,
      "y": 32,
      "z": -32,
      "name": "Rock_Volcanic"
    },
    {
      "x": -49,
      "y": 33,
      "z": -32,
      "name": "Rock_Volcanic"
    },
    {
      "x": -49,
      "y": 34,
      "z": -32,
      "name": "Rock_Volcanic"
    },
    {
      "x": -49,
      "y": 35,
      "z": -32,
      "name": "Rock_Volcanic"
    },
    {
      "x": -49,
      "y": 36,
      "z": -32,
      "name": "Rock_Volcanic_Cobble"
    },
    {
      "x": -49,
      "y": 37,
      "z": -32,
      "name": "Rock_Volcanic_Cobble"
    },
    {
      "x": -49,
      "y": 38,
      "z": -32,
      "name": "Rock_Volcanic_Cobble"
    },
    {
      "x": -49,
      "y": 39,
      "z": -32,
      "name": "Rock_Volcanic_Brick"
    },
    {
      "x": -49,
      "y": 40,
      "z": -32,
      "name": "Rock_Volcanic_Cobble"
    },
    {
      "x": -49,
      "y": 41,
      "z": -32,
      "name": "Rock_Volcanic_Brick"
    },
    {
      "x": -49,
      "y": 42,
      "z": -32,
      "name": "Rock_Volcanic_Brick"
    },
    {
      "x": -49,
      "y": 43,
      "z": -32,
      "name": "Deco_Bone_Skulls"
    },
    {
      "x": -49,
      "y": 22,
      "z": -31,
      "name": "Rock_Volcanic"
    },
    {
      "x": -49,
      "y": 23,
      "z": -31,
      "name": "Rock_Volcanic"
    },
    {
      "x": -49,
      "y": 24,
      "z": -31,
      "name": "Rock_Volcanic"
    },
    {
      "x": -49,
      "y": 25,
      "z": -31,
      "name": "Rock_Volcanic"
    },
    {
      "x": -49,
      "y": 26,
      "z": -31,
      "name": "Rock_Volcanic"
    },
    {
      "x": -49,
      "y": 27,
      "z": -31,
      "name": "Rock_Volcanic"
    },
    {
      "x": -49,
      "y": 28,
      "z": -31,
      "name": "Rock_Volcanic"
    },
    {
      "x": -49,
      "y": 29,
      "z": -31,
      "name": "Rock_Volcanic"
    },
    {
      "x": -49,
      "y": 30,
      "z": -31,
      "name": "Rock_Volcanic"
    },
    {
      "x": -49,
      "y": 31,
      "z": -31,
      "name": "Rock_Volcanic"
    },
    {
      "x": -49,
      "y": 32,
      "z": -31,
      "name": "Rock_Volcanic"
    },
    {
      "x": -49,
      "y": 33,
      "z": -31,
      "name": "Rock_Volcanic"
    },
    {
      "x": -49,
      "y": 34,
      "z": -31,
      "name": "Rock_Volcanic"
    },
    {
      "x": -49,
      "y": 35,
      "z": -31,
      "name": "Rock_Volcanic_Cobble"
    },
    {
      "x": -49,
      "y": 36,
      "z": -31,
      "name": "Rock_Volcanic_Cobble"
    },
    {
      "x": -49,
      "y": 37,
      "z": -31,
      "name": "Rock_Volcanic_Cobble"
    },
    {
      "x": -49,
      "y": 38,
      "z": -31,
      "name": "Rock_Volcanic_Cobble"
    },
    {
      "x": -49,
      "y": 39,
      "z": -31,
      "name": "Rock_Volcanic_Cobble"
    },
    {
      "x": -49,
      "y": 40,
      "z": -31,
      "name": "Rock_Volcanic_Brick"
    },
    {
      "x": -49,
      "y": 41,
      "z": -31,
      "name": "Rock_Volcanic_Brick"
    },
    {
      "x": -49,
      "y": 23,
      "z": -30,
      "name": "Rock_Volcanic"
    },
    {
      "x": -49,
      "y": 24,
      "z": -30,
      "name": "Rock_Volcanic"
    },
    {
      "x": -49,
      "y": 25,
      "z": -30,
      "name": "Rock_Volcanic"
    },
    {
      "x": -49,
      "y": 26,
      "z": -30,
      "name": "Rock_Volcanic"
    },
    {
      "x": -49,
      "y": 27,
      "z": -30,
      "name": "Rock_Volcanic"
    },
    {
      "x": -49,
      "y": 28,
      "z": -30,
      "name": "Rock_Volcanic"
    },
    {
      "x": -49,
      "y": 29,
      "z": -30,
      "name": "Rock_Volcanic"
    },
    {
      "x": -49,
      "y": 30,
      "z": -30,
      "name": "Rock_Volcanic"
    },
    {
      "x": -49,
      "y": 31,
      "z": -30,
      "name": "Rock_Volcanic"
    },
    {
      "x": -49,
      "y": 32,
      "z": -30,
      "name": "Rock_Volcanic"
    },
    {
      "x": -49,
      "y": 33,
      "z": -30,
      "name": "Rock_Volcanic"
    },
    {
      "x": -49,
      "y": 34,
      "z": -30,
      "name": "Rock_Volcanic_Cobble"
    },
    {
      "x": -49,
      "y": 35,
      "z": -30,
      "name": "Rock_Volcanic_Cobble"
    },
    {
      "x": -49,
      "y": 36,
      "z": -30,
      "name": "Rock_Volcanic_Cobble"
    },
    {
      "x": -49,
      "y": 37,
      "z": -30,
      "name": "Rock_Volcanic_Cobble"
    },
    {
      "x": -49,
      "y": 38,
      "z": -30,
      "name": "Rock_Volcanic_Cobble"
    },
    {
      "x": -49,
      "y": 39,
      "z": -30,
      "name": "Rock_Volcanic_Brick"
    },
    {
      "x": -49,
      "y": 40,
      "z": -30,
      "name": "Rock_Volcanic_Brick"
    },
    {
      "x": -49,
      "y": 41,
      "z": -30,
      "name": "Rock_Gold_Brick_Smooth"
    },
    {
      "x": -49,
      "y": 24,
      "z": -29,
      "name": "Rock_Volcanic"
    },
    {
      "x": -49,
      "y": 25,
      "z": -29,
      "name": "Rock_Volcanic"
    },
    {
      "x": -49,
      "y": 26,
      "z": -29,
      "name": "Rock_Volcanic"
    },
    {
      "x": -49,
      "y": 27,
      "z": -29,
      "name": "Rock_Volcanic"
    },
    {
      "x": -49,
      "y": 28,
      "z": -29,
      "name": "Rock_Volcanic"
    },
    {
      "x": -49,
      "y": 29,
      "z": -29,
      "name": "Rock_Volcanic"
    },
    {
      "x": -49,
      "y": 30,
      "z": -29,
      "name": "Rock_Volcanic"
    },
    {
      "x": -49,
      "y": 31,
      "z": -29,
      "name": "Rock_Volcanic"
    },
    {
      "x": -49,
      "y": 32,
      "z": -29,
      "name": "Rock_Volcanic"
    },
    {
      "x": -49,
      "y": 33,
      "z": -29,
      "name": "Rock_Volcanic"
    },
    {
      "x": -49,
      "y": 34,
      "z": -29,
      "name": "Rock_Volcanic_Cobble"
    },
    {
      "x": -49,
      "y": 35,
      "z": -29,
      "name": "Rock_Volcanic_Brick"
    },
    {
      "x": -49,
      "y": 36,
      "z": -29,
      "name": "Rock_Volcanic_Brick"
    },
    {
      "x": -49,
      "y": 37,
      "z": -29,
      "name": "Rock_Volcanic_Brick"
    },
    {
      "x": -49,
      "y": 38,
      "z": -29,
      "name": "Rock_Volcanic_Brick"
    },
    {
      "x": -49,
      "y": 39,
      "z": -29,
      "name": "Rock_Volcanic_Brick"
    },
    {
      "x": -49,
      "y": 25,
      "z": -28,
      "name": "Rock_Volcanic"
    },
    {
      "x": -49,
      "y": 26,
      "z": -28,
      "name": "Rock_Volcanic"
    },
    {
      "x": -49,
      "y": 27,
      "z": -28,
      "name": "Rock_Volcanic"
    },
    {
      "x": -49,
      "y": 28,
      "z": -28,
      "name": "Rock_Volcanic"
    },
    {
      "x": -49,
      "y": 29,
      "z": -28,
      "name": "Rock_Volcanic"
    },
    {
      "x": -49,
      "y": 30,
      "z": -28,
      "name": "Rock_Volcanic"
    },
    {
      "x": -49,
      "y": 31,
      "z": -28,
      "name": "Rock_Volcanic"
    },
    {
      "x": -49,
      "y": 32,
      "z": -28,
      "name": "Rock_Volcanic"
    },
    {
      "x": -49,
      "y": 36,
      "z": -28,
      "name": "Rock_Volcanic_Brick"
    },
    {
      "x": -49,
      "y": 37,
      "z": -28,
      "name": "Rock_Volcanic_Brick"
    },
    {
      "x": -49,
      "y": 38,
      "z": -28,
      "name": "Rock_Volcanic_Brick"
    },
    {
      "x": -49,
      "y": 39,
      "z": -28,
      "name": "Rock_Volcanic_Brick"
    },
    {
      "x": -49,
      "y": 26,
      "z": -27,
      "name": "Rock_Volcanic"
    },
    {
      "x": -49,
      "y": 27,
      "z": -27,
      "name": "Rock_Volcanic"
    },
    {
      "x": -49,
      "y": 28,
      "z": -27,
      "name": "Rock_Volcanic"
    },
    {
      "x": -49,
      "y": 29,
      "z": -27,
      "name": "Rock_Volcanic"
    },
    {
      "x": -49,
      "y": 30,
      "z": -27,
      "name": "Rock_Volcanic"
    },
    {
      "x": -49,
      "y": 27,
      "z": -26,
      "name": "Rock_Volcanic"
    },
    {
      "x": -49,
      "y": 28,
      "z": -26,
      "name": "Rock_Volcanic"
    },
    {
      "x": -49,
      "y": 29,
      "z": -26,
      "name": "Rock_Volcanic"
    },
    {
      "x": -49,
      "y": 30,
      "z": -26,
      "name": "Rock_Volcanic"
    },
    {
      "x": -49,
      "y": 27,
      "z": -25,
      "name": "Rock_Volcanic"
    },
    {
      "x": -49,
      "y": 28,
      "z": -25,
      "name": "Rock_Volcanic"
    },
    {
      "x": -49,
      "y": 29,
      "z": -25,
      "name": "Rock_Volcanic"
    },
    {
      "x": -49,
      "y": 30,
      "z": -25,
      "name": "Rock_Volcanic"
    },
    {
      "x": -49,
      "y": 27,
      "z": -24,
      "name": "Rock_Volcanic"
    },
    {
      "x": -49,
      "y": 28,
      "z": -24,
      "name": "Rock_Volcanic"
    },
    {
      "x": -49,
      "y": 29,
      "z": -24,
      "name": "Rock_Volcanic"
    },
    {
      "x": -49,
      "y": 30,
      "z": -24,
      "name": "Rock_Volcanic"
    },
    {
      "x": -49,
      "y": 31,
      "z": -24,
      "name": "Rock_Volcanic"
    },
    {
      "x": -49,
      "y": 37,
      "z": -24,
      "name": "Rock_Volcanic_Brick"
    },
    {
      "x": -49,
      "y": 38,
      "z": -24,
      "name": "Rock_Volcanic_Brick"
    },
    {
      "x": -49,
      "y": 39,
      "z": -24,
      "name": "Rock_Volcanic_Brick"
    },
    {
      "x": -49,
      "y": 26,
      "z": -23,
      "name": "Rock_Volcanic"
    },
    {
      "x": -49,
      "y": 27,
      "z": -23,
      "name": "Rock_Volcanic"
    },
    {
      "x": -49,
      "y": 28,
      "z": -23,
      "name": "Rock_Volcanic"
    },
    {
      "x": -49,
      "y": 29,
      "z": -23,
      "name": "Rock_Volcanic"
    },
    {
      "x": -49,
      "y": 30,
      "z": -23,
      "name": "Rock_Volcanic"
    },
    {
      "x": -49,
      "y": 31,
      "z": -23,
      "name": "Rock_Volcanic"
    },
    {
      "x": -49,
      "y": 32,
      "z": -23,
      "name": "Rock_Volcanic"
    },
    {
      "x": -49,
      "y": 33,
      "z": -23,
      "name": "Rock_Volcanic"
    },
    {
      "x": -49,
      "y": 34,
      "z": -23,
      "name": "Rock_Volcanic_Cobble"
    },
    {
      "x": -49,
      "y": 36,
      "z": -23,
      "name": "Rock_Volcanic_Brick"
    },
    {
      "x": -49,
      "y": 37,
      "z": -23,
      "name": "Rock_Volcanic_Brick"
    },
    {
      "x": -49,
      "y": 38,
      "z": -23,
      "name": "Rock_Volcanic_Brick"
    },
    {
      "x": -49,
      "y": 39,
      "z": -23,
      "name": "Rock_Volcanic_Brick"
    },
    {
      "x": -49,
      "y": 25,
      "z": -22,
      "name": "Rock_Volcanic"
    },
    {
      "x": -49,
      "y": 26,
      "z": -22,
      "name": "Rock_Volcanic"
    },
    {
      "x": -49,
      "y": 27,
      "z": -22,
      "name": "Rock_Volcanic"
    },
    {
      "x": -49,
      "y": 28,
      "z": -22,
      "name": "Rock_Volcanic"
    },
    {
      "x": -49,
      "y": 29,
      "z": -22,
      "name": "Rock_Volcanic"
    },
    {
      "x": -49,
      "y": 30,
      "z": -22,
      "name": "Rock_Volcanic"
    },
    {
      "x": -49,
      "y": 31,
      "z": -22,
      "name": "Rock_Volcanic"
    },
    {
      "x": -49,
      "y": 32,
      "z": -22,
      "name": "Rock_Volcanic"
    },
    {
      "x": -49,
      "y": 33,
      "z": -22,
      "name": "Rock_Volcanic"
    },
    {
      "x": -49,
      "y": 34,
      "z": -22,
      "name": "Rock_Volcanic_Cobble"
    },
    {
      "x": -49,
      "y": 35,
      "z": -22,
      "name": "Rock_Volcanic_Cobble"
    },
    {
      "x": -49,
      "y": 36,
      "z": -22,
      "name": "Rock_Volcanic_Cobble"
    },
    {
      "x": -49,
      "y": 37,
      "z": -22,
      "name": "Rock_Volcanic_Cobble"
    },
    {
      "x": -49,
      "y": 38,
      "z": -22,
      "name": "Rock_Volcanic_Cobble"
    },
    {
      "x": -49,
      "y": 39,
      "z": -22,
      "name": "Rock_Volcanic_Brick"
    },
    {
      "x": -49,
      "y": 40,
      "z": -22,
      "name": "Rock_Volcanic_Brick"
    },
    {
      "x": -49,
      "y": 27,
      "z": -21,
      "name": "Rock_Volcanic"
    },
    {
      "x": -49,
      "y": 28,
      "z": -21,
      "name": "Rock_Volcanic"
    },
    {
      "x": -49,
      "y": 29,
      "z": -21,
      "name": "Rock_Volcanic"
    },
    {
      "x": -49,
      "y": 30,
      "z": -21,
